Workbook

Sheet 前提
A1: 売上目標 再設定 FY2026（2026-05〜2027-04）― 前提・入力値（すべて税抜）
A2: 青字＝入力値（変更可）、黄色＝特に見直しが必要な仮置き。黒字＝数式。他シートはこのシートを参照。
A4: 税込→税抜 係数（媒体計測ROASは税込） | B4: 1.1 | C4: 媒体の購入金額は税込。÷1.1で税抜換算
A5: 前年売上のうち広告経由の比率 | B5: 0.15 | C5: 前年は計測破損のため推定。8月実績の広告売り比率16%を参考に仮置き
A6: 会社WEB予算（年間・税抜） | B6: 280000000 | C6: 会社WEB年度予算ファイル
A7: ストレッチ目標（年間・税抜） | B7: 320000000 | C7: ユーザー指定
A8: 3ストアの広告予算シェア（10月〜、各ストア） | B8: 0.15 | C8: HOUDINI/NORRONA/PU 各15%、FULLMARKS 55%
A11: 実績（5〜8月・税抜）
A12: 月 | B12: 売上実績 | C12: 会社予算 | D12: 前年同月
A13: 2026-05 | B13: 10878769 | C13: 16500000 | D13: 12569387 | E13: 出典: 会社WEB年度予算ファイル（税抜）。予算比は5〜8月計で114%
A14: 2026-06 | B14: 11689179 | C14: 16500000 | D14: 10282993
A15: 2026-07 | B15: 31677600 | C15: 17000000 | D15: 11017920
A16: 2026-08 | B16: 26669593 | C16: 21000000 | D16: 21492906
A17: 5〜8月 計 | B17: =SUM(B13:B16) | C17: =SUM(C13:C16) | D17: =SUM(D13:D16)
A20: 月別入力（9〜4月）
A21: 月 | B21: 会社予算 | C21: 前年同月 | D21: 自然売上 成長率 | E21: 広告費合計(通常+イベント) | F21: うちイベント予備費 | G21: ROAS 達成度
A22: 2026-09 | B22: 15000000 | C22: 9504761 | D22: 1 | E22: 698422 | F22: 48422 | G22: 0.7 | H22: 成長率＝前年同月の自然売上に対する伸び（1.00＝前年並み）。10月は3ストア稼働で1.10、2月は前年6,369万が突出値のため0.75、4月は0.90。ROAS達成度＝想定ROASに掛ける係数。9月は広告刷新直後(9/1〜3実績ROAS3.3)のため0.70、10月は新ストア立ち上げで0.85。広告費は「広告予算計画_金額確定版」の月額。
A23: 2026-10 | B23: 29000000 | C23: 16850103 | D23: 1.1 | E23: 1052086 | F23: 0 | G23: 0.85
A24: 2026-11 | B24: 30000000 | C24: 28306061 | D24: 1 | E24: 1087156 | F24: 0 | G24: 1
A25: 2026-12 | B25: 36000000 | C25: 27709798 | D25: 1 | E25: 1292364 | F25: 100000 | G25: 1
A26: 2027-01 | B26: 26000000 | C26: 22725973 | D26: 1 | E26: 981947 | F26: 0 | G26: 1
A27: 2027-02 | B27: 41000000 | C27: 63694086 | D27: 0.75 | E27: 1372225 | F27: 250000 | G27: 1
A28: 2027-03 | B28: 15500000 | C28: 14646068 | D28: 1 | E28: 856599 | F28: 50000 | G28: 1
A29: 2027-04 | B29: 16500000 | C29: 24663324 | D29: 0.9 | E29: 771530 | F29: 0 | G29: 1
A30: 計 | B30: =SUM(B22:B29) | C30: =SUM(C22:C29) | E30: =SUM(E22:E29) | F30: =SUM(F22:F29)
A33: ライン定義（広告配分比率・ROAS・自然売上シェア）
A34: ストア | B34: ブランド/枠 | C34: 9月 配分比率 | D34: 10月〜 配分比率 | E34: 枠種別 | F34: 想定ROAS(税込計測) | G34: 自然売上シェア 9月 | H34: 自然売上シェア 10月〜(FM=移管前 / 新ストア=潜在規模) | I34: 純増率(新ストア) | J34: 備考
A35: FULLMARKS STORE | B35: HOUDINI | C35: 0.27 | D35: 0.2 | E35: FM | F35: 14 | G35: 0.55 | H35: 0.55 | J35: 8月ROAS17.3。HOUDINI STORE開店後、移管分(潜在規模×(1−純増率))を差し引く
A36: FULLMARKS STORE | B36: NORRØNA | C36: 0.07 | D36: 0.06 | E36: FM | F36: 4 | G36: 0.12 | H36: 0.12 | J36: 8月ROAS1.1→文言/シリーズ別に刷新。NORRONA STORE開店後に移管分を差し引く
A37: FULLMARKS STORE | B37: POC | C37: 0.09 | D37: 0.12 | E37: FM | F37: 5 | G37: 0.1 | H37: 0.1 | J37: 8月ROAS3.9。専用ストア無しのため強化
A38: FULLMARKS STORE | B38: ACLIMA | C38: 0.05 | D38: 0.06 | E38: FM | F38: 4 | G38: 0.06 | H38: 0.06 | J38: MetaのCLKはROAS6
A39: FULLMARKS STORE | B39: HESTRA | C39: 0.04 | D39: 0.08 | E39: FM | F39: 5 | G39: 0.07 | H39: 0.07 | J39: 未広告→指名検索を新設。10〜1月が本番。フィード未掲載81件の修正が前提
A40: FULLMARKS STORE | B40: その他(KANG/PLUS ONE WORKS/POW/SR) | C40: 0.01 | D40: 0.02 | E40: FM | F40: 3 | G40: 0.1 | H40: 0.1 | J40: PU STORE開店後に移管分を差し引く
A41: FULLMARKS STORE | B41: 共通: 店舗指名検索 | C41: 0.17 | D41: 0.18 | E41: FM | F41: 14 | G41: 0 | H41: 0 | J41: 8月ROAS15.8。ブランド横断のため自然売上は配分しない
A42: FULLMARKS STORE | B42: 共通: 商品連動(ショッピング/カタログ) | C42: 0.3 | D42: 0.28 | E42: FM | F42: 8 | G42: 0 | H42: 0 | J42: 8月ROAS7.4。アウトレット除外後の水準で要観察
A43: FULLMARKS STORE | B43: 共通: イベント予備費(SW/年末/セール) | E43: EV | F43: 5 | G43: 0 | H43: 0 | J43: EC企画の告知用。月次表の『イベント』列
A44: HOUDINI STORE | B44: HOUDINI | E44: ST | F44: 8 | G44: 0 | H44: 0.25 | I44: 0.5 | J44: 9月末開店。潜在規模＝FULLMARKS自然売上の25%。うち純増50%、残り50%はFULLMARKSからの移管
A45: NORRONA STORE | B45: NORRØNA | E45: ST | F45: 5 | G45: 0 | H45: 0.08 | I45: 0.5 | J45: 10月開店。潜在規模8%、純増50%
A46: PU STORE | B46: PLUS ONE WORKS | E46: ST | F46: 3 | G46: 0 | H46: 0.05 | I46: 0.6 | J46: 10月開店。潜在規模5%、純増60%（自社ブランドで新規比率高め）
A47: チェック（比率・シェアの合計） | C47: =SUM(C35:C46) | D47: =SUM(D35:D46) | G47: =SUM(G35:G46) | H47: =SUMIF($E$35:$E$46,"FM",H35:H46) | J47: 配分比率は各100%。自然売上シェアはFULLMARKS行の合計が100%（新ストアの潜在規模は別枠）
...

Sheet 月別目標
A1: 月別 売上目標（税抜）― 広告費 × ROAS ＋ 自然売上 vs 会社予算2.8億
A2: 会社予算2.8億はFULLMARKS STORE単体の予算。売上目標(4ストア計)＝FULLMARKS単体＋新ストアの純増。自然売上＝前年同月×(1−前年広告比率)×成長率。広告売上＝広告費×想定ROAS×ROAS達成度÷1.1。
A4: 月 | B4: 会社予算(FM単体) | C4: 前年同月 | D4: 自然売上(4ストア計) | E4: 広告費 | F4: 広告売上 | G4: 売上目標(4ストア計) | H4: 予算差 | I4: 前年比 | J4: 広告費率 | K4: 累計 目標 | L4: 累計 会社予算 | M4: 累計 予算差 | N4: 備考 | O4: FULLMARKS STORE 単体(移管後) | P4: FM単体 予算差 | Q4: 新ストア 売上(3店計) | R4: 自然売上プール(FM換算・移管前)
A5: 5〜8月 実績 | B5: =前提!$C$17 | C5: =前提!$D$17 | G5: =前提!$B$17 | H5: =G5-B5 | I5: =G5/C5 | K5: =G5 | L5: =B5 | M5: =K5-L5 | N5: 実績。広告売り/自然売りの内訳は計測破損のため省略 | O5: =G5 | P5: =O5-B5 | Q5: 0
A6: 2026-09 | B6: =前提!B22 | C6: =前提!C22 | D6: =ストア別ブランド別!E17 | E6: =ストア別ブランド別!C17 | F6: =ストア別ブランド別!D17 | G6: =D6+F6 | H6: =G6-B6 | I6: =IF(C6=0,0,G6/C6) | J6: =IF(G6=0,0,E6/G6) | K6: =K5+G6 | L6: =L5+B6 | M6: =K6-L6 | N6: SW企画。前年950万は年間最弱月 | O6: =ストア別ブランド別!F20 | P6: =O6-B6 | Q6: =G6-O6 | R6: =C6*(1-前提!$B$5)*前提!D22
A7: 2026-10 | B7: =前提!B23 | C7: =前提!C23 | D7: =ストア別ブランド別!I17 | E7: =ストア別ブランド別!G17 | F7: =ストア別ブランド別!H17 | G7: =D7+F7 | H7: =G7-B7 | I7: =IF(C7=0,0,G7/C7) | J7: =IF(G7=0,0,E7/G7) | K7: =K6+G7 | L7: =L6+B7 | M7: =K7-L7 | N7: 3ストア稼働・広告増額。前年1,685万 | O7: =ストア別ブランド別!J20 | P7: =O7-B7 | Q7: =G7-O7 | R7: =C7*(1-前提!$B$5)*前提!D23
A8: 2026-11 | B8: =前提!B24 | C8: =前提!C24 | D8: =ストア別ブランド別!M17 | E8: =ストア別ブランド別!K17 | F8: =ストア別ブランド別!L17 | G8: =D8+F8 | H8: =G8-B8 | I8: =IF(C8=0,0,G8/C8) | J8: =IF(G8=0,0,E8/G8) | K8: =K7+G8 | L8: =L7+B8 | M8: =K8-L8 | N8: 繁忙期入り | O8: =ストア別ブランド別!N20 | P8: =O8-B8 | Q8: =G8-O8 | R8: =C8*(1-前提!$B$5)*前提!D24
A9: 2026-12 | B9: =前提!B25 | C9: =前提!C25 | D9: =ストア別ブランド別!Q17 | E9: =ストア別ブランド別!O17 | F9: =ストア別ブランド別!P17 | G9: =D9+F9 | H9: =G9-B9 | I9: =IF(C9=0,0,G9/C9) | J9: =IF(G9=0,0,E9/G9) | K9: =K8+G9 | L9: =L8+B9 | M9: =K9-L9 | N9: 年末商戦（予備10万） | O9: =ストア別ブランド別!R20 | P9: =O9-B9 | Q9: =G9-O9 | R9: =C9*(1-前提!$B$5)*前提!D25
A10: 2027-01 | B10: =前提!B26 | C10: =前提!C26 | D10: =ストア別ブランド別!U17 | E10: =ストア別ブランド別!S17 | F10: =ストア別ブランド別!T17 | G10: =D10+F10 | H10: =G10-B10 | I10: =IF(C10=0,0,G10/C10) | J10: =IF(G10=0,0,E10/G10) | K10: =K9+G10 | L10: =L9+B10 | M10: =K10-L10 | N10: 冬物実需 | O10: =ストア別ブランド別!V20 | P10: =O10-B10 | Q10: =G10-O10 | R10: =C10*(1-前提!$B$5)*前提!D26
A11: 2027-02 | B11: =前提!B27 | C11: =前提!C27 | D11: =ストア別ブランド別!Y17 | E11: =ストア別ブランド別!W17 | F11: =ストア別ブランド別!X17 | G11: =D11+F11 | H11: =G11-B11 | I11: =IF(C11=0,0,G11/C11) | J11: =IF(G11=0,0,E11/G11) | K11: =K10+G11 | L11: =L10+B11 | M11: =K11-L11 | N11: 冬セール（予備25万）。前年6,369万は突出値 | O11: =ストア別ブランド別!Z20 | P11: =O11-B11 | Q11: =G11-O11 | R11: =C11*(1-前提!$B$5)*前提!D27
A12: 2027-03 | B12: =前提!B28 | C12: =前提!C28 | D12: =ストア別ブランド別!AC17 | E12: =ストア別ブランド別!AA17 | F12: =ストア別ブランド別!AB17 | G12: =D12+F12 | H12: =G12-B12 | I12: =IF(C12=0,0,G12/C12) | J12: =IF(G12=0,0,E12/G12) | K12: =K11+G12 | L12: =L11+B12 | M12: =K12-L12 | N12: 端境期（予備5万） | O12: =ストア別ブランド別!AD20 | P12: =O12-B12 | Q12: =G12-O12 | R12: =C12*(1-前提!$B$5)*前提!D28
A13: 2027-04 | B13: =前提!B29 | C13: =前提!C29 | D13: =ストア別ブランド別!AG17 | E13: =ストア別ブランド別!AE17 | F13: =ストア別ブランド別!AF17 | G13: =D13+F13 | H13: =G13-B13 | I13: =IF(C13=0,0,G13/C13) | J13: =IF(G13=0,0,E13/G13) | K13: =K12+G13 | L13: =L12+B13 | M13: =K13-L13 | N13: 調整月 | O13: =ストア別ブランド別!AH20 | P13: =O13-B13 | Q13: =G13-O13 | R13: =C13*(1-前提!$B$5)*前提!D29
A14: 年間 合計 | B14: =B5+SUM(B6:B13) | C14: =C5+SUM(C6:C13) | D14: =SUM(D6:D13) | E14: =SUM(E6:E13) | F14: =SUM(F6:F13) | G14: =G5+SUM(G6:G13) | H14: =G14-B14 | I14: =G14/C14 | J14: =E14/G14 | O14: =O5+SUM(O6:O13) | P14: =O14-B14 | Q14: =SUM(Q6:Q13) | R14: =SUM(R6:R13)
A16: 年間目標 vs 会社予算2.8億 | G16: =G14-前提!$B$6
A17: 年間目標 vs ストレッチ3.2億 | G17: =G14-前提!$B$7
A18: 年間 広告売上ROAS（税抜） | G18: =F14/E14
A19: FULLMARKS STORE 単体 vs 会社予算2.8億 | G19: =O14-前提!$B$6
A20: 新ストア 売上（年間・3店計） | G20: =Q14

Sheet ストア別ブランド別
A1: ストア別・ブランド別 月次目標（税抜）＝ 広告費 × ROAS ÷ 1.1 ＋ 自然売上
A2: 各月4列: 広告費 / 広告売上 / 自然売上 / 合計。広告売上＝広告費×想定ROAS×月別ROAS達成度÷1.1。新ストアの自然売上＝FULLMARKS自然売上×潜在規模。FULLMARKS側は移管分（潜在規模×(1−純増率)）を差し引く。
C3: 2026-09 | G3: 2026-10 | K3: 2026-11 | O3: 2026-12 | S3: 2027-01 | W3: 2027-02 | AA3: 2027-03 | AE3: 2027-04 | AI3: 年間(9〜4月)
A4: ストア | B4: ブランド/枠 | C4: 広告費 | D4: 広告売上 | E4: 自然売上 | F4: 合計 | G4: 広告費 | H4: 広告売上 | I4: 自然売上 | J4: 合計 | K4: 広告費 | L4: 広告売上 | M4: 自然売上 | N4: 合計 | O4: 広告費 | P4: 広告売上 | Q4: 自然売上 | R4: 合計 | S4: 広告費 | T4: 広告売上 | U4: 自然売上 | V4: 合計 | W4: 広告費 | X4: 広告売上 | Y4: 自然売上 | Z4: 合計 | AA4: 広告費 | AB4: 広告売上 | AC4: 自然売上 | AD4: 合計 | AE4: 広告費 | AF4: 広告売上 | AG4: 自然売上 | AH4: 合計 | AI4: 広告費 | AJ4: 広告売上 | AK4: 自然売上 | AL4: 合計
A5: FULLMARKS STORE | B5: HOUDINI | C5: =(前提!$E$22-前提!$F$22)*IF(TRUE,1,1-3*前提!$B$8)*IF(TRUE,前提!$C$35,前提!$D$35) | D5: =C5*前提!$F$35*前提!$G$22/前提!$B$4 | E5: =月別目標!$R$6*IF(TRUE,前提!$G$35,前提!$H$35)-IF(TRUE,0,月別目標!$R$6*前提!$H$44*(1-前提!$I$44)) | F5: =D5+E5 | G5: =(前提!$E$23-前提!$F$23)*IF(FALSE,1,1-3*前提!$B$8)*IF(FALSE,前提!$C$35,前提!$D$35) | H5: =G5*前提!$F$35*前提!$G$23/前提!$B$4 | I5: =月別目標!$R$7*IF(FALSE,前提!$G$35,前提!$H$35)-IF(FALSE,0,月別目標!$R$7*前提!$H$44*(1-前提!$I$44)) | J5: =H5+I5 | K5: =(前提!$E$24-前提!$F$24)*IF(FALSE,1,1-3*前提!$B$8)*IF(FALSE,前提!$C$35,前提!$D$35) | L5: =K5*前提!$F$35*前提!$G$24/前提!$B$4 | M5: =月別目標!$R$8*IF(FALSE,前提!$G$35,前提!$H$35)-IF(FALSE,0,月別目標!$R$8*前提!$H$44*(1-前提!$I$44)) | N5: =L5+M5 | O5: =(前提!$E$25-前提!$F$25)*IF(FALSE,1,1-3*前提!$B$8)*IF(FALSE,前提!$C$35,前提!$D$35) | P5: =O5*前提!$F$35*前提!$G$25/前提!$B$4 | Q5: =月別目標!$R$9*IF(FALSE,前提!$G$35,前提!$H$35)-IF(FALSE,0,月別目標!$R$9*前提!$H$44*(1-前提!$I$44)) | R5: =P5+Q5 | S5: =(前提!$E$26-前提!$F$26)*IF(FALSE,1,1-3*前提!$B$8)*IF(FALSE,前提!$C$35,前提!$D$35) | T5: =S5*前提!$F$35*前提!$G$26/前提!$B$4 | U5: =月別目標!$R$10*IF(FALSE,前提!$G$35,前提!$H$35)-IF(FALSE,0,月別目標!$R$10*前提!$H$44*(1-前提!$I$44)) | V5: =T5+U5 | W5: =(前提!$E$27-前提!$F$27)*IF(FALSE,1,1-3*前提!$B$8)*IF(FALSE,前提!$C$35,前提!$D$35) | X5: =W5*前提!$F$35*前提!$G$27/前提!$B$4 | Y5: =月別目標!$R$11*IF(FALSE,前提!$G$35,前提!$H$35)-IF(FALSE,0,月別目標!$R$11*前提!$H$44*(1-前提!$I$44)) | Z5: =X5+Y5 | AA5: =(前提!$E$28-前提!$F$28)*IF(FALSE,1,1-3*前提!$B$8)*IF(FALSE,前提!$C$35,前提!$D$35) | AB5: =AA5*前提!$F$35*前提!$G$28/前提!$B$4 | AC5: =月別目標!$R$12*IF(FALSE,前提!$G$35,前提!$H$35)-IF(FALSE,0,月別目標!$R$12*前提!$H$44*(1-前提!$I$44)) | AD5: =AB5+AC5 | AE5: =(前提!$E$29-前提!$F$29)*IF(FALSE,1,1-3*前提!$B$8)*IF(FALSE,前提!$C$35,前提!$D$35) | AF5: =AE5*前提!$F$35*前提!$G$29/前提!$B$4 | AG5: =月別目標!$R$13*IF(FALSE,前提!$G$35,前提!$H$35)-IF(FALSE,0,月別目標!$R$13*前提!$H$44*(1-前提!$I$44)) | AH5: =AF5+AG5 | AI5: =C5+G5+K5+O5+S5+W5+AA5+AE5 | AJ5: =D5+H5+L5+P5+T5+X5+AB5+AF5 | AK5: =E5+I5+M5+Q5+U5+Y5+AC5+AG5 | AL5: =F5+J5+N5+R5+V5+Z5+AD5+AH5
A6: FULLMARKS STORE | B6: NORRØNA | C6: =(前提!$E$22-前提!$F$22)*IF(TRUE,1,1-3*前提!$B$8)*IF(TRUE,前提!$C$36,前提!$D$36) | D6: =C6*前提!$F$36*前提!$G$22/前提!$B$4 | E6: =月別目標!$R$6*IF(TRUE,前提!$G$36,前提!$H$36)-IF(TRUE,0,月別目標!$R$6*前提!$H$45*(1-前提!$I$45)) | F6: =D6+E6 | G6: =(前提!$E$23-前提!$F$23)*IF(FALSE,1,1-3*前提!$B$8)*IF(FALSE,前提!$C$36,前提!$D$36) | H6: =G6*前提!$F$36*前提!$G$23/前提!$B$4 | I6: =月別目標!$R$7*IF(FALSE,前提!$G$36,前提!$H$36)-IF(FALSE,0,月別目標!$R$7*前提!$H$45*(1-前提!$I$45)) | J6: =H6+I6 | K6: =(前提!$E$24-前提!$F$24)*IF(FALSE,1,1-3*前提!$B$8)*IF(FALSE,前提!$C$36,前提!$D$36) | L6: =K6*前提!$F$36*前提!$G$24/前提!$B$4 | M6: =月別目標!$R$8*IF(FALSE,前提!$G$36,前提!$H$36)-IF(FALSE,0,月別目標!$R$8*前提!$H$45*(1-前提!$I$45)) | N6: =L6+M6 | O6: =(前提!$E$25-前提!$F$25)*IF(FALSE,1,1-3*前提!$B$8)*IF(FALSE,前提!$C$36,前提!$D$36) | P6: =O6*前提!$F$36*前提!$G$25/前提!$B$4 | Q6: =月別目標!$R$9*IF(FALSE,前提!$G$36,前提!$H$36)-IF(FALSE,0,月別目標!$R$9*前提!$H$45*(1-前提!$I$45)) | R6: =P6+Q6 | S6: =(前提!$E$26-前提!$F$26)*IF(FALSE,1,1-3*前提!$B$8)*IF(FALSE,前提!$C$36,前提!$D$36) | T6: =S6*前提!$F$36*前提!$G$26/前提!$B$4 | U6: =月別目標!$R$10*IF(FALSE,前提!$G$36,前提!$H$36)-IF(FALSE,0,月別目標!$R$10*前提!$H$45*(1-前提!$I$45)) | V6: =T6+U6 | W6: =(前提!$E$27-前提!$F$27)*IF(FALSE,1,1-3*前提!$B$8)*IF(FALSE,前提!$C$36,前提!$D$36) | X6: =W6*前提!$F$36*前提!$G$27/前提!$B$4 | Y6: =月別目標!$R$11*IF(FALSE,前提!$G$36,前提!$H$36)-IF(FALSE,0,月別目標!$R$11*前提!$H$45*(1-前提!$I$45)) | Z6: =X6+Y6 | AA6: =(前提!$E$28-前提!$F$28)*IF(FALSE,1,1-3*前提!$B$8)*IF(FALSE,前提!$C$36,前提!$D$36) | AB6: =AA6*前提!$F$36*前提!$G$28/前提!$B$4 | AC6: =月別目標!$R$12*IF(FALSE,前提!$G$36,前提!$H$36)-IF(FALSE,0,月別目標!$R$12*前提!$H$45*(1-前提!$I$45)) | AD6: =AB6+AC6 | AE6: =(前提!$E$29-前提!$F$29)*IF(FALSE,1,1-3*前提!$B$8)*IF(FALSE,前提!$C$36,前提!$D$36) | AF6: =AE6*前提!$F$36*前提!$G$29/前提!$B$4 | AG6: =月別目標!$R$13*IF(FALSE,前提!$G$36,前提!$H$36)-IF(FALSE,0,月別目標!$R$13*前提!$H$45*(1-前提!$I$45)) | AH6: =AF6+AG6 | AI6: =C6+G6+K6+O6+S6+W6+AA6+AE6 | AJ6: =D6+H6+L6+P6+T6+X6+AB6+AF6 | AK6: =E6+I6+M6+Q6+U6+Y6+AC6+AG6 | AL6: =F6+J6+N6+R6+V6+Z6+AD6+AH6
A7: FULLMARKS STORE | B7: POC | C7: =(前提!$E$22-前提!$F$22)*IF(TRUE,1,1-3*前提!$B$8)*IF(TRUE,前提!$C$37,前提!$D$37) | D7: =C7*前提!$F$37*前提!$G$22/前提!$B$4 | E7: =月別目標!$R$6*IF(TRUE,前提!$G$37,前提!$H$37) | F7: =D7+E7 | G7: =(前提!$E$23-前提!$F$23)*IF(FALSE,1,1-3*前提!$B$8)*IF(FALSE,前提!$C$37,前提!$D$37) | H7: =G7*前提!$F$37*前提!$G$23/前提!$B$4 | I7: =月別目標!$R$7*IF(FALSE,前提!$G$37,前提!$H$37) | J7: =H7+I7 | K7: =(前提!$E$24-前提!$F$24)*IF(FALSE,1,1-3*前提!$B$8)*IF(FALSE,前提!$C$37,前提!$D$37) | L7: =K7*前提!$F$37*前提!$G$24/前提!$B$4 | M7: =月別目標!$R$8*IF(FALSE,前提!$G$37,前提!$H$37) | N7: =L7+M7 | O7: =(前提!$E$25-前提!$F$25)*IF(FALSE,1,1-3*前提!$B$8)*IF(FALSE,前提!$C$37,前提!$D$37) | P7: =O7*前提!$F$37*前提!$G$25/前提!$B$4 | Q7: =月別目標!$R$9*IF(FALSE,前提!$G$37,前提!$H$37) | R7: =P7+Q7 | S7: =(前提!$E$26-前提!$F$26)*IF(FALSE,1,1-3*前提!$B$8)*IF(FALSE,前提!$C$37,前提!$D$37) | T7: =S7*前提!$F$37*前提!$G$26/前提!$B$4 | U7: =月別目標!$R$10*IF(FALSE,前提!$G$37,前提!$H$37) | V7: =T7+U7 | W7: =(前提!$E$27-前提!$F$27)*IF(FALSE,1,1-3*前提!$B$8)*IF(FALSE,前提!$C$37,前提!$D$37) | X7: =W7*前提!$F$37*前提!$G$27/前提!$B$4 | Y7: =月別目標!$R$11*IF(FALSE,前提!$G$37,前提!$H$37) | Z7: =X7+Y7 | AA7: =(前提!$E$28-前提!$F$28)*IF(FALSE,1,1-3*前提!$B$8)*IF(FALSE,前提!$C$37,前提!$D$37) | AB7: =AA7*前提!$F$37*前提!$G$28/前提!$B$4 | AC7: =月別目標!$R$12*IF(FALSE,前提!$G$37,前提!$H$37) | AD7: =AB7+AC7 | AE7: =(前提!$E$29-前提!$F$29)*IF(FALSE,1,1-3*前提!$B$8)*IF(FALSE,前提!$C$37,前提!$D$37) | AF7: =AE7*前提!$F$37*前提!$G$29/前提!$B$4 | AG7: =月別目標!$R$13*IF(FALSE,前提!$G$37,前提!$H$37) | AH7: =AF7+AG7 | AI7: =C7+G7+K7+O7+S7+W7+AA7+AE7 | AJ7: =D7+H7+L7+P7+T7+X7+AB7+AF7 | AK7: =E7+I7+M7+Q7+U7+Y7+AC7+AG7 | AL7: =F7+J7+N7+R7+V7+Z7+AD7+AH7
A8: FULLMARKS STORE | B8: ACLIMA | C8: =(前提!$E$22-前提!$F$22)*IF(TRUE,1,1-3*前提!$B$8)*IF(TRUE,前提!$C$38,前提!$D$38) | D8: =C8*前提!$F$38*前提!$G$22/前提!$B$4 | E8: =月別目標!$R$6*IF(TRUE,前提!$G$38,前提!$H$38) | F8: =D8+E8 | G8: =(前提!$E$23-前提!$F$23)*IF(FALSE,1,1-3*前提!$B$8)*IF(FALSE,前提!$C$38,前提!$D$38) | H8: =G8*前提!$F$38*前提!$G$23/前提!$B$4 | I8: =月別目標!$R$7*IF(FALSE,前提!$G$38,前提!$H$38) | J8: =H8+I8 | K8: =(前提!$E$24-前提!$F$24)*IF(FALSE,1,1-3*前提!$B$8)*IF(FALSE,前提!$C$38,前提!$D$38) | L8: =K8*前提!$F$38*前提!$G$24/前提!$B$4 | M8: =月別目標!$R$8*IF(FALSE,前提!$G$38,前提!$H$38) | N8: =L8+M8 | O8: =(前提!$E$25-前提!$F$25)*IF(FALSE,1,1-3*前提!$B$8)*IF(FALSE,前提!$C$38,前提!$D$38) | P8: =O8*前提!$F$38*前提!$G$25/前提!$B$4 | Q8: =月別目標!$R$9*IF(FALSE,前提!$G$38,前提!$H$38) | R8: =P8+Q8 | S8: =(前提!$E$26-前提!$F$26)*IF(FALSE,1,1-3*前提!$B$8)*IF(FALSE,前提!$C$38,前提!$D$38) | T8: =S8*前提!$F$38*前提!$G$26/前提!$B$4 | U8: =月別目標!$R$10*IF(FALSE,前提!$G$38,前提!$H$38) | V8: =T8+U8 | W8: =(前提!$E$27-前提!$F$27)*IF(FALSE,1,1-3*前提!$B$8)*IF(FALSE,前提!$C$38,前提!$D$38) | X8: =W8*前提!$F$38*前提!$G$27/前提!$B$4 | Y8: =月別目標!$R$11*IF(FALSE,前提!$G$38,前提!$H$38) | Z8: =X8+Y8 | AA8: =(前提!$E$28-前提!$F$28)*IF(FALSE,1,1-3*前提!$B$8)*IF(FALSE,前提!$C$38,前提!$D$38) | AB8: =AA8*前提!$F$38*前提!$G$28/前提!$B$4 | AC8: =月別目標!$R$12*IF(FALSE,前提!$G$38,前提!$H$38) | AD8: =AB8+AC8 | AE8: =(前提!$E$29-前提!$F$29)*IF(FALSE,1,1-3*前提!$B$8)*IF(FALSE,前提!$C$38,前提!$D$38) | AF8: =AE8*前提!$F$38*前提!$G$29/前提!$B$4 | AG8: =月別目標!$R$13*IF(FALSE,前提!$G$38,前提!$H$38) | AH8: =AF8+AG8 | AI8: =C8+G8+K8+O8+S8+W8+AA8+AE8 | AJ8: =D8+H8+L8+P8+T8+X8+AB8+AF8 | AK8: =E8+I8+M8+Q8+U8+Y8+AC8+AG8 | AL8: =F8+J8+N8+R8+V8+Z8+AD8+AH8
A9: FULLMARKS STORE | B9: HESTRA | C9: =(前提!$E$22-前提!$F$22)*IF(TRUE,1,1-3*前提!$B$8)*IF(TRUE,前提!$C$39,前提!$D$39) | D9: =C9*前提!$F$39*前提!$G$22/前提!$B$4 | E9: =月別目標!$R$6*IF(TRUE,前提!$G$39,前提!$H$39) | F9: =D9+E9 | G9: =(前提!$E$23-前提!$F$23)*IF(FALSE,1,1-3*前提!$B$8)*IF(FALSE,前提!$C$39,前提!$D$39) | H9: =G9*前提!$F$39*前提!$G$23/前提!$B$4 | I9: =月別目標!$R$7*IF(FALSE,前提!$G$39,前提!$H$39) | J9: =H9+I9 | K9: =(前提!$E$24-前提!$F$24)*IF(FALSE,1,1-3*前提!$B$8)*IF(FALSE,前提!$C$39,前提!$D$39) | L9: =K9*前提!$F$39*前提!$G$24/前提!$B$4 | M9: =月別目標!$R$8*IF(FALSE,前提!$G$39,前提!$H$39) | N9: =L9+M9 | O9: =(前提!$E$25-前提!$F$25)*IF(FALSE,1,1-3*前提!$B$8)*IF(FALSE,前提!$C$39,前提!$D$39) | P9: =O9*前提!$F$39*前提!$G$25/前提!$B$4 | Q9: =月別目標!$R$9*IF(FALSE,前提!$G$39,前提!$H$39) | R9: =P9+Q9 | S9: =(前提!$E$26-前提!$F$26)*IF(FALSE,1,1-3*前提!$B$8)*IF(FALSE,前提!$C$39,前提!$D$39) | T9: =S9*前提!$F$39*前提!$G$26/前提!$B$4 | U9: =月別目標!$R$10*IF(FALSE,前提!$G$39,前提!$H$39) | V9: =T9+U9 | W9: =(前提!$E$27-前提!$F$27)*IF(FALSE,1,1-3*前提!$B$8)*IF(FALSE,前提!$C$39,前提!$D$39) | X9: =W9*前提!$F$39*前提!$G$27/前提!$B$4 | Y9: =月別目標!$R$11*IF(FALSE,前提!$G$39,前提!$H$39) | Z9: =X9+Y9 | AA9: =(前提!$E$28-前提!$F$28)*IF(FALSE,1,1-3*前提!$B$8)*IF(FALSE,前提!$C$39,前提!$D$39) | AB9: =AA9*前提!$F$39*前提!$G$28/前提!$B$4 | AC9: =月別目標!$R$12*IF(FALSE,前提!$G$39,前提!$H$39) | AD9: =AB9+AC9 | AE9: =(前提!$E$29-前提!$F$29)*IF(FALSE,1,1-3*前提!$B$8)*IF(FALSE,前提!$C$39,前提!$D$39) | AF9: =AE9*前提!$F$39*前提!$G$29/前提!$B$4 | AG9: =月別目標!$R$13*IF(FALSE,前提!$G$39,前提!$H$39) | AH9: =AF9+AG9 | AI9: =C9+G9+K9+O9+S9+W9+AA9+AE9 | AJ9: =D9+H9+L9+P9+T9+X9+AB9+AF9 | AK9: =E9+I9+M9+Q9+U9+Y9+AC9+AG9 | AL9: =F9+J9+N9+R9+V9+Z9+AD9+AH9
A10: FULLMARKS STORE | B10: その他(KANG/PLUS ONE WORKS/POW/SR) | C10: =(前提!$E$22-前提!$F$22)*IF(TRUE,1,1-3*前提!$B$8)*IF(TRUE,前提!$C$40,前提!$D$40) | D10: =C10*前提!$F$40*前提!$G$22/前提!$B$4 | E10: =月別目標!$R$6*IF(TRUE,前提!$G$40,前提!$H$40)-IF(TRUE,0,月別目標!$R$6*前提!$H$46*(1-前提!$I$46)) | F10: =D10+E10 | G10: =(前提!$E$23-前提!$F$23)*IF(FALSE,1,1-3*前提!$B$8)*IF(FALSE,前提!$C$40,前提!$D$40) | H10: =G10*前提!$F$40*前提!$G$23/前提!$B$4 | I10: =月別目標!$R$7*IF(FALSE,前提!$G$40,前提!$H$40)-IF(FALSE,0,月別目標!$R$7*前提!$H$46*(1-前提!$I$46)) | J10: =H10+I10 | K10: =(前提!$E$24-前提!$F$24)*IF(FALSE,1,1-3*前提!$B$8)*IF(FALSE,前提!$C$40,前提!$D$40) | L10: =K10*前提!$F$40*前提!$G$24/前提!$B$4 | M10: =月別目標!$R$8*IF(FALSE,前提!$G$40,前提!$H$40)-IF(FALSE,0,月別目標!$R$8*前提!$H$46*(1-前提!$I$46)) | N10: =L10+M10 | O10: =(前提!$E$25-前提!$F$25)*IF(FALSE,1,1-3*前提!$B$8)*IF(FALSE,前提!$C$40,前提!$D$40) | P10: =O10*前提!$F$40*前提!$G$25/前提!$B$4 | Q10: =月別目標!$R$9*IF(FALSE,前提!$G$40,前提!$H$40)-IF(FALSE,0,月別目標!$R$9*前提!$H$46*(1-前提!$I$46)) | R10: =P10+Q10 | S10: =(前提!$E$26-前提!$F$26)*IF(FALSE,1,1-3*前提!$B$8)*IF(FALSE,前提!$C$40,前提!$D$40) | T10: =S10*前提!$F$40*前提!$G$26/前提!$B$4 | U10: =月別目標!$R$10*IF(FALSE,前提!$G$40,前提!$H$40)-IF(FALSE,0,月別目標!$R$10*前提!$H$46*(1-前提!$I$46)) | V10: =T10+U10 | W10: =(前提!$E$27-前提!$F$27)*IF(FALSE,1,1-3*前提!$B$8)*IF(FALSE,前提!$C$40,前提!$D$40) | X10: =W10*前提!$F$40*前提!$G$27/前提!$B$4 | Y10: =月別目標!$R$11*IF(FALSE,前提!$G$40,前提!$H$40)-IF(FALSE,0,月別目標!$R$11*前提!$H$46*(1-前提!$I$46)) | Z10: =X10+Y10 | AA10: =(前提!$E$28-前提!$F$28)*IF(FALSE,1,1-3*前提!$B$8)*IF(FALSE,前提!$C$40,前提!$D$40) | AB10: =AA10*前提!$F$40*前提!$G$28/前提!$B$4 | AC10: =月別目標!$R$12*IF(FALSE,前提!$G$40,前提!$H$40)-IF(FALSE,0,月別目標!$R$12*前提!$H$46*(1-前提!$I$46)) | AD10: =AB10+AC10 | AE10: =(前提!$E$29-前提!$F$29)*IF(FALSE,1,1-3*前提!$B$8)*IF(FALSE,前提!$C$40,前提!$D$40) | AF10: =AE10*前提!$F$40*前提!$G$29/前提!$B$4 | AG10: =月別目標!$R$13*IF(FALSE,前提!$G$40,前提!$H$40)-IF(FALSE,0,月別目標!$R$13*前提!$H$46*(1-前提!$I$46)) | AH10: =AF10+AG10 | AI10: =C10+G10+K10+O10+S10+W10+AA10+AE10 | AJ10: =D10+H10+L10+P10+T10+X10+AB10+AF10 | AK10: =E10+I10+M10+Q10+U10+Y10+AC10+AG10 | AL10: =F10+J10+N10+R10+V10+Z10+AD10+AH10
A11: FULLMARKS STORE | B11: 共通: 店舗指名検索 | C11: =(前提!$E$22-前提!$F$22)*IF(TRUE,1,1-3*前提!$B$8)*IF(TRUE,前提!$C$41,前提!$D$41) | D11: =C11*前提!$F$41*前提!$G$22/前提!$B$4 | E11: =月別目標!$R$6*IF(TRUE,前提!$G$41,前提!$H$41) | F11: =D11+E11 | G11: =(前提!$E$23-前提!$F$23)*IF(FALSE,1,1-3*前提!$B$8)*IF(FALSE,前提!$C$41,前提!$D$41) | H11: =G11*前提!$F$41*前提!$G$23/前提!$B$4 | I11: =月別目標!$R$7*IF(FALSE,前提!$G$41,前提!$H$41) | J11: =H11+I11 | K11: =(前提!$E$24-前提!$F$24)*IF(FALSE,1,1-3*前提!$B$8)*IF(FALSE,前提!$C$41,前提!$D$41) | L11: =K11*前提!$F$41*前提!$G$24/前提!$B$4 | M11: =月別目標!$R$8*IF(FALSE,前提!$G$41,前提!$H$41) | N11: =L11+M11 | O11: =(前提!$E$25-前提!$F$25)*IF(FALSE,1,1-3*前提!$B$8)*IF(FALSE,前提!$C$41,前提!$D$41) | P11: =O11*前提!$F$41*前提!$G$25/前提!$B$4 | Q11: =月別目標!$R$9*IF(FALSE,前提!$G$41,前提!$H$41) | R11: =P11+Q11 | S11: =(前提!$E$26-前提!$F$26)*IF(FALSE,1,1-3*前提!$B$8)*IF(FALSE,前提!$C$41,前提!$D$41) | T11: =S11*前提!$F$41*前提!$G$26/前提!$B$4 | U11: =月別目標!$R$10*IF(FALSE,前提!$G$41,前提!$H$41) | V11: =T11+U11 | W11: =(前提!$E$27-前提!$F$27)*IF(FALSE,1,1-3*前提!$B$8)*IF(FALSE,前提!$C$41,前提!$D$41) | X11: =W11*前提!$F$41*前提!$G$27/前提!$B$4 | Y11: =月別目標!$R$11*IF(FALSE,前提!$G$41,前提!$H$41) | Z11: =X11+Y11 | AA11: =(前提!$E$28-前提!$F$28)*IF(FALSE,1,1-3*前提!$B$8)*IF(FALSE,前提!$C$41,前提!$D$41) | AB11: =AA11*前提!$F$41*前提!$G$28/前提!$B$4 | AC11: =月別目標!$R$12*IF(FALSE,前提!$G$41,前提!$H$41) | AD11: =AB11+AC11 | AE11: =(前提!$E$29-前提!$F$29)*IF(FALSE,1,1-3*前提!$B$8)*IF(FALSE,前提!$C$41,前提!$D$41) | AF11: =AE11*前提!$F$41*前提!$G$29/前提!$B$4 | AG11: =月別目標!$R$13*IF(FALSE,前提!$G$41,前提!$H$41) | AH11: =AF11+AG11 | AI11: =C11+G11+K11+O11+S11+W11+AA11+AE11 | AJ11: =D11+H11+L11+P11+T11+X11+AB11+AF11 | AK11: =E11+I11+M11+Q11+U11+Y11+AC11+AG11 | AL11: =F11+J11+N11+R11+V11+Z11+AD11+AH11
A12: FULLMARKS STORE | B12: 共通: 商品連動(ショッピング/カタログ) | C12: =(前提!$E$22-前提!$F$22)*IF(TRUE,1,1-3*前提!$B$8)*IF(TRUE,前提!$C$42,前提!$D$42) | D12: =C12*前提!$F$42*前提!$G$22/前提!$B$4 | E12: =月別目標!$R$6*IF(TRUE,前提!$G$42,前提!$H$42) | F12: =D12+E12 | G12: =(前提!$E$23-前提!$F$23)*IF(FALSE,1,1-3*前提!$B$8)*IF(FALSE,前提!$C$42,前提!$D$42) | H12: =G12*前提!$F$42*前提!$G$23/前提!$B$4 | I12: =月別目標!$R$7*IF(FALSE,前提!$G$42,前提!$H$42) | J12: =H12+I12 | K12: =(前提!$E$24-前提!$F$24)*IF(FALSE,1,1-3*前提!$B$8)*IF(FALSE,前提!$C$42,前提!$D$42) | L12: =K12*前提!$F$42*前提!$G$24/前提!$B$4 | M12: =月別目標!$R$8*IF(FALSE,前提!$G$42,前提!$H$42) | N12: =L12+M12 | O12: =(前提!$E$25-前提!$F$25)*IF(FALSE,1,1-3*前提!$B$8)*IF(FALSE,前提!$C$42,前提!$D$42) | P12: =O12*前提!$F$42*前提!$G$25/前提!$B$4 | Q12: =月別目標!$R$9*IF(FALSE,前提!$G$42,前提!$H$42) | R12: =P12+Q12 | S12: =(前提!$E$26-前提!$F$26)*IF(FALSE,1,1-3*前提!$B$8)*IF(FALSE,前提!$C$42,前提!$D$42) | T12: =S12*前提!$F$42*前提!$G$26/前提!$B$4 | U12: =月別目標!$R$10*IF(FALSE,前提!$G$42,前提!$H$42) | V12: =T12+U12 | W12: =(前提!$E$27-前提!$F$27)*IF(FALSE,1,1-3*前提!$B$8)*IF(FALSE,前提!$C$42,前提!$D$42) | X12: =W12*前提!$F$42*前提!$G$27/前提!$B$4 | Y12: =月別目標!$R$11*IF(FALSE,前提!$G$42,前提!$H$42) | Z12: =X12+Y12 | AA12: =(前提!$E$28-前提!$F$28)*IF(FALSE,1,1-3*前提!$B$8)*IF(FALSE,前提!$C$42,前提!$D$42) | AB12: =AA12*前提!$F$42*前提!$G$28/前提!$B$4 | AC12: =月別目標!$R$12*IF(FALSE,前提!$G$42,前提!$H$42) | AD12: =AB12+AC12 | AE12: =(前提!$E$29-前提!$F$29)*IF(FALSE,1,1-3*前提!$B$8)*IF(FALSE,前提!$C$42,前提!$D$42) | AF12: =AE12*前提!$F$42*前提!$G$29/前提!$B$4 | AG12: =月別目標!$R$13*IF(FALSE,前提!$G$42,前提!$H$42) | AH12: =AF12+AG12 | AI12: =C12+G12+K12+O12+S12+W12+AA12+AE12 | AJ12: =D12+H12+L12+P12+T12+X12+AB12+AF12 | AK12: =E12+I12+M12+Q12+U12+Y12+AC12+AG12 | AL12: =F12+J12+N12+R12+V12+Z12+AD12+AH12
A13: FULLMARKS STORE | B13: 共通: イベント予備費(SW/年末/セール) | C13: =前提!$F$22 | D13: =C13*前提!$F$43*前提!$G$22/前提!$B$4 | E13: =月別目標!$R$6*IF(TRUE,前提!$G$43,前提!$H$43) | F13: =D13+E13 | G13: =前提!$F$23 | H13: =G13*前提!$F$43*前提!$G$23/前提!$B$4 | I13: =月別目標!$R$7*IF(FALSE,前提!$G$43,前提!$H$43) | J13: =H13+I13 | K13: =前提!$F$24 | L13: =K13*前提!$F$43*前提!$G$24/前提!$B$4 | M13: =月別目標!$R$8*IF(FALSE,前提!$G$43,前提!$H$43) | N13: =L13+M13 | O13: =前提!$F$25 | P13: =O13*前提!$F$43*前提!$G$25/前提!$B$4 | Q13: =月別目標!$R$9*IF(FALSE,前提!$G$43,前提!$H$43) | R13: =P13+Q13 | S13: =前提!$F$26 | T13: =S13*前提!$F$43*前提!$G$26/前提!$B$4 | U13: =月別目標!$R$10*IF(FALSE,前提!$G$43,前提!$H$43) | V13: =T13+U13 | W13: =前提!$F$27 | X13: =W13*前提!$F$43*前提!$G$27/前提!$B$4 | Y13: =月別目標!$R$11*IF(FALSE,前提!$G$43,前提!$H$43) | Z13: =X13+Y13 | AA13: =前提!$F$28 | AB13: =AA13*前提!$F$43*前提!$G$28/前提!$B$4 | AC13: =月別目標!$R$12*IF(FALSE,前提!$G$43,前提!$H$43) | AD13: =AB13+AC13 | AE13: =前提!$F$29 | AF13: =AE13*前提!$F$43*前提!$G$29/前提!$B$4 | AG13: =月別目標!$R$13*IF(FALSE,前提!$G$43,前提!$H$43) | AH13: =AF13+AG13 | AI13: =C13+G13+K13+O13+S13+W13+AA13+AE13 | AJ13: =D13+H13+L13+P13+T13+X13+AB13+AF13 | AK13: =E13+I13+M13+Q13+U13+Y13+AC13+AG13 | AL13: =F13+J13+N13+R13+V13+Z13+AD13+AH13
A14: HOUDINI STORE | B14: HOUDINI | C14: =IF(TRUE,0,(前提!$E$22-前提!$F$22)*前提!$B$8) | D14: =C14*前提!$F$44*前提!$G$22/前提!$B$4 | E14: =IF(TRUE,0,月別目標!$R$6*前提!$H$44) | F14: =D14+E14 | G14: =IF(FALSE,0,(前提!$E$23-前提!$F$23)*前提!$B$8) | H14: =G14*前提!$F$44*前提!$G$23/前提!$B$4 | I14: =IF(FALSE,0,月別目標!$R$7*前提!$H$44) | J14: =H14+I14 | K14: =IF(FALSE,0,(前提!$E$24-前提!$F$24)*前提!$B$8) | L14: =K14*前提!$F$44*前提!$G$24/前提!$B$4 | M14: =IF(FALSE,0,月別目標!$R$8*前提!$H$44) | N14: =L14+M14 | O14: =IF(FALSE,0,(前提!$E$25-前提!$F$25)*前提!$B$8) | P14: =O14*前提!$F$44*前提!$G$25/前提!$B$4 | Q14: =IF(FALSE,0,月別目標!$R$9*前提!$H$44) | R14: =P14+Q14 | S14: =IF(FALSE,0,(前提!$E$26-前提!$F$26)*前提!$B$8) | T14: =S14*前提!$F$44*前提!$G$26/前提!$B$4 | U14: =IF(FALSE,0,月別目標!$R$10*前提!$H$44) | V14: =T14+U14 | W14: =IF(FALSE,0,(前提!$E$27-前提!$F$27)*前提!$B$8) | X14: =W14*前提!$F$44*前提!$G$27/前提!$B$4 | Y14: =IF(FALSE,0,月別目標!$R$11*前提!$H$44) | Z14: =X14+Y14 | AA14: =IF(FALSE,0,(前提!$E$28-前提!$F$28)*前提!$B$8) | AB14: =AA14*前提!$F$44*前提!$G$28/前提!$B$4 | AC14: =IF(FALSE,0,月別目標!$R$12*前提!$H$44) | AD14: =AB14+AC14 | AE14: =IF(FALSE,0,(前提!$E$29-前提!$F$29)*前提!$B$8) | AF14: =AE14*前提!$F$44*前提!$G$29/前提!$B$4 | AG14: =IF(FALSE,0,月別目標!$R$13*前提!$H$44) | AH14: =AF14+AG14 | AI14: =C14+G14+K14+O14+S14+W14+AA14+AE14 | AJ14: =D14+H14+L14+P14+T14+X14+AB14+AF14 | AK14: =E14+I14+M14+Q14+U14+Y14+AC14+AG14 | AL14: =F14+J14+N14+R14+V14+Z14+AD14+AH14
A15: NORRONA STORE | B15: NORRØNA | C15: =IF(TRUE,0,(前提!$E$22-前提!$F$22)*前提!$B$8) | D15: =C15*前提!$F$45*前提!$G$22/前提!$B$4 | E15: =IF(TRUE,0,月別目標!$R$6*前提!$H$45) | F15: =D15+E15 | G15: =IF(FALSE,0,(前提!$E$23-前提!$F$23)*前提!$B$8) | H15: =G15*前提!$F$45*前提!$G$23/前提!$B$4 | I15: =IF(FALSE,0,月別目標!$R$7*前提!$H$45) | J15: =H15+I15 | K15: =IF(FALSE,0,(前提!$E$24-前提!$F$24)*前提!$B$8) | L15: =K15*前提!$F$45*前提!$G$24/前提!$B$4 | M15: =IF(FALSE,0,月別目標!$R$8*前提!$H$45) | N15: =L15+M15 | O15: =IF(FALSE,0,(前提!$E$25-前提!$F$25)*前提!$B$8) | P15: =O15*前提!$F$45*前提!$G$25/前提!$B$4 | Q15: =IF(FALSE,0,月別目標!$R$9*前提!$H$45) | R15: =P15+Q15 | S15: =IF(FALSE,0,(前提!$E$26-前提!$F$26)*前提!$B$8) | T15: =S15*前提!$F$45*前提!$G$26/前提!$B$4 | U15: =IF(FALSE,0,月別目標!$R$10*前提!$H$45) | V15: =T15+U15 | W15: =IF(FALSE,0,(前提!$E$27-前提!$F$27)*前提!$B$8) | X15: =W15*前提!$F$45*前提!$G$27/前提!$B$4 | Y15: =IF(FALSE,0,月別目標!$R$11*前提!$H$45) | Z15: =X15+Y15 | AA15: =IF(FALSE,0,(前提!$E$28-前提!$F$28)*前提!$B$8) | AB15: =AA15*前提!$F$45*前提!$G$28/前提!$B$4 | AC15: =IF(FALSE,0,月別目標!$R$12*前提!$H$45) | AD15: =AB15+AC15 | AE15: =IF(FALSE,0,(前提!$E$29-前提!$F$29)*前提!$B$8) | AF15: =AE15*前提!$F$45*前提!$G$29/前提!$B$4 | AG15: =IF(FALSE,0,月別目標!$R$13*前提!$H$45) | AH15: =AF15+AG15 | AI15: =C15+G15+K15+O15+S15+W15+AA15+AE15 | AJ15: =D15+H15+L15+P15+T15+X15+AB15+AF15 | AK15: =E15+I15+M15+Q15+U15+Y15+AC15+AG15 | AL15: =F15+J15+N15+R15+V15+Z15+AD15+AH15
A16: PU STORE | B16: PLUS ONE WORKS | C16: =IF(TRUE,0,(前提!$E$22-前提!$F$22)*前提!$B$8) | D16: =C16*前提!$F$46*前提!$G$22/前提!$B$4 | E16: =IF(TRUE,0,月別目標!$R$6*前提!$H$46) | F16: =D16+E16 | G16: =IF(FALSE,0,(前提!$E$23-前提!$F$23)*前提!$B$8) | H16: =G16*前提!$F$46*前提!$G$23/前提!$B$4 | I16: =IF(FALSE,0,月別目標!$R$7*前提!$H$46) | J16: =H16+I16 | K16: =IF(FALSE,0,(前提!$E$24-前提!$F$24)*前提!$B$8) | L16: =K16*前提!$F$46*前提!$G$24/前提!$B$4 | M16: =IF(FALSE,0,月別目標!$R$8*前提!$H$46) | N16: =L16+M16 | O16: =IF(FALSE,0,(前提!$E$25-前提!$F$25)*前提!$B$8) | P16: =O16*前提!$F$46*前提!$G$25/前提!$B$4 | Q16: =IF(FALSE,0,月別目標!$R$9*前提!$H$46) | R16: =P16+Q16 | S16: =IF(FALSE,0,(前提!$E$26-前提!$F$26)*前提!$B$8) | T16: =S16*前提!$F$46*前提!$G$26/前提!$B$4 | U16: =IF(FALSE,0,月別目標!$R$10*前提!$H$46) | V16: =T16+U16 | W16: =IF(FALSE,0,(前提!$E$27-前提!$F$27)*前提!$B$8) | X16: =W16*前提!$F$46*前提!$G$27/前提!$B$4 | Y16: =IF(FALSE,0,月別目標!$R$11*前提!$H$46) | Z16: =X16+Y16 | AA16: =IF(FALSE,0,(前提!$E$28-前提!$F$28)*前提!$B$8) | AB16: =AA16*前提!$F$46*前提!$G$28/前提!$B$4 | AC16: =IF(FALSE,0,月別目標!$R$12*前提!$H$46) | AD16: =AB16+AC16 | AE16: =IF(FALSE,0,(前提!$E$29-前提!$F$29)*前提!$B$8) | AF16: =AE16*前提!$F$46*前提!$G$29/前提!$B$4 | AG16: =IF(FALSE,0,月別目標!$R$13*前提!$H$46) | AH16: =AF16+AG16 | AI16: =C16+G16+K16+O16+S16+W16+AA16+AE16 | AJ16: =D16+H16+L16+P16+T16+X16+AB16+AF16 | AK16: =E16+I16+M16+Q16+U16+Y16+AC16+AG16 | AL16: =F16+J16+N16+R16+V16+Z16+AD16+AH16
A17: 4ストア合計 | C17: =SUM(C5:C16) | D17: =SUM(D5:D16) | E17: =SUM(E5:E16) | F17: =SUM(F5:F16) | G17: =SUM(G5:G16) | H17: =SUM(H5:H16) | I17: =SUM(I5:I16) | J17: =SUM(J5:J16) | ... AL17: =SUM(AL5:AL16)
A19: ストア別 小計
A20: FULLMARKS STORE | C20: =SUMIF($A$5:$A$16,$A20,C$5:C$16) | D20: =SUMIF($A$5:$A$16,$A20,D$5:D$16) | E20: =SUMIF($A$5:$A$16,$A20,E$5:E$16) | F20: =SUMIF($A$5:$A$16,$A20,F$5:F$16) | G20: =SUMIF($A$5:$A$16,$A20,G$5:G$16) | H20: =SUMIF($A$5:$A$16,$A20,H$5:H$16) | I20: =SUMIF($A$5:$A$16,$A20,I$5:I$16) | J20: =SUMIF($A$5:$A$16,$A20,J$5:J$16) | ... AL20: =SUMIF($A$5:$A$16,$A20,AL$5:AL$16)
A21: HOUDINI STORE | C21: =SUMIF($A$5:$A$16,$A21,C$5:C$16) | D21: =SUMIF($A$5:$A$16,$A21,D$5:D$16) | E21: =SUMIF($A$5:$A$16,$A21,E$5:E$16) | F21: =SUMIF($A$5:$A$16,$A21,F$5:F$16) | G21: =SUMIF($A$5:$A$16,$A21,G$5:G$16) | H21: =SUMIF($A$5:$A$16,$A21,H$5:H$16) | I21: =SUMIF($A$5:$A$16,$A21,I$5:I$16) | J21: =SUMIF($A$5:$A$16,$A21,J$5:J$16) | ... AL21: =SUMIF($A$5:$A$16,$A21,AL$5:AL$16)
A22: NORRONA STORE | C22: =SUMIF($A$5:$A$16,$A22,C$5:C$16) | D22: =SUMIF($A$5:$A$16,$A22,D$5:D$16) | E22: =SUMIF($A$5:$A$16,$A22,E$5:E$16) | F22: =SUMIF($A$5:$A$16,$A22,F$5:F$16) | G22: =SUMIF($A$5:$A$16,$A22,G$5:G$16) | H22: =SUMIF($A$5:$A$16,$A22,H$5:H$16) | I22: =SUMIF($A$5:$A$16,$A22,I$5:I$16) | J22: =SUMIF($A$5:$A$16,$A22,J$5:J$16) | ... AL22: =SUMIF($A$5:$A$16,$A22,AL$5:AL$16)
A23: PU STORE | C23: =SUMIF($A$5:$A$16,$A23,C$5:C$16) | D23: =SUMIF($A$5:$A$16,$A23,D$5:D$16) | E23: =SUMIF($A$5:$A$16,$A23,E$5:E$16) | F23: =SUMIF($A$5:$A$16,$A23,F$5:F$16) | G23: =SUMIF($A$5:$A$16,$A23,G$5:G$16) | H23: =SUMIF($A$5:$A$16,$A23,H$5:H$16) | I23: =SUMIF($A$5:$A$16,$A23,I$5:I$16) | J23: =SUMIF($A$5:$A$16,$A23,J$5:J$16) | ... AL23: =SUMIF($A$5:$A$16,$A23,AL$5:AL$16)
A25: 年間 想定ROAS（税抜ベース＝広告売上÷広告費） | AJ25: =IF(AI17=0,0,AJ17/AI17)

Sheet シナリオ
A1: シナリオ比較（年間売上・税抜）
A2: 自然売上とROASの達成度を掛けて年間売上を試算。青字は変更可。
A4: シナリオ | B4: 自然売上 達成度 | C4: ROAS 達成度 | D4: 年間売上(4ストア計) | E4: vs 2.8億 | F4: vs 3.2億 | G4: 9〜4月 必要な月平均 | H4: FULLMARKS単体(年間) | I4: FM単体 vs 2.8億
A5: 保守（前年の広告比率25%相当＝自然売上0.88・ROAS0.8） | B5: 0.88 | C5: 0.8 | D5: =前提!$B$17+月別目標!$D$14*B5+月別目標!$F$14*C5 | E5: =D5-前提!$B$6 | F5: =D5-前提!$B$7 | G5: =(D5-前提!$B$17)/8 | H5: =前提!$B$17+(ストア別ブランド別!AK20)*B5+(ストア別ブランド別!AJ20)*C5 | I5: =H5-前提!$B$6
A6: 標準（前提シートどおり） | B6: 1 | C6: 1 | D6: =前提!$B$17+月別目標!$D$14*B6+月別目標!$F$14*C6 | E6: =D6-前提!$B$6 | F6: =D6-前提!$B$7 | G6: =(D6-前提!$B$17)/8 | H6: =前提!$B$17+(ストア別ブランド別!AK20)*B6+(ストア別ブランド別!AJ20)*C6 | I6: =H6-前提!$B$6
A7: 強気（自然+5%・ROAS1.2倍） | B7: 1.05 | C7: 1.2 | D7: =前提!$B$17+月別目標!$D$14*B7+月別目標!$F$14*C7 | E7: =D7-前提!$B$6 | F7: =D7-前提!$B$7 | G7: =(D7-前提!$B$17)/8 | H7: =前提!$B$17+(ストア別ブランド別!AK20)*B7+(ストア別ブランド別!AJ20)*C7 | I7: =H7-前提!$B$6
A9: 読み方: 保守でも2.8億に届くかが判断基準。届かない場合は10月・12月の広告費増額か、企画で自然売上を上積みする。

Sheet 月次チェック
A1: 月次チェック（税抜）― 実績を入れると、2.8億に対する残り必要額が出る
A2: 毎月、C列に会社ファイルの売上実績（税抜）を入力。未入力の月は目標値で仮置きして累計を出す。
A4: 月 | B4: 目標 | C4: 実績（入力） | D4: 目標差 | E4: 累計 目標 | F4: 累計 実績/見込 | G4: 累計 会社予算 | H4: 2.8億まで残り | I4: 残り月の必要月平均 | J4: メモ
A5: 5〜8月 実績 | B5: =前提!$C$17 | C5: =前提!$B$17 | D5: =C5-B5 | E5: =B5 | F5: =C5 | G5: =前提!$C$17 | H5: =前提!$B$6-F5 | I5: =H5/8
A6: 2026-09 | B6: =月別目標!G6 | D6: =IF(C6="","",C6-B6) | E6: =E5+B6 | F6: =F5+IF(C6="",B6,C6) | G6: =G5+月別目標!B6 | H6: =前提!$B$6-F6 | I6: =IF(7=0,0,H6/7) | J6: 実績が空欄の月は目標で仮置き
A7: 2026-10 | B7: =月別目標!G7 | D7: =IF(C7="","",C7-B7) | E7: =E6+B7 | F7: =F6+IF(C7="",B7,C7) | G7: =G6+月別目標!B7 | H7: =前提!$B$6-F7 | I7: =IF(6=0,0,H7/6)
A8: 2026-11 | B8: =月別目標!G8 | D8: =IF(C8="","",C8-B8) | E8: =E7+B8 | F8: =F7+IF(C8="",B8,C8) | G8: =G7+月別目標!B8 | H8: =前提!$B$6-F8 | I8: =IF(5=0,0,H8/5)
A9: 2026-12 | B9: =月別目標!G9 | D9: =IF(C9="","",C9-B9) | E9: =E8+B9 | F9: =F8+IF(C9="",B9,C9) | G9: =G8+月別目標!B9 | H9: =前提!$B$6-F9 | I9: =IF(4=0,0,H9/4)
A10: 2027-01 | B10: =月別目標!G10 | D10: =IF(C10="","",C10-B10) | E10: =E9+B10 | F10: =F9+IF(C10="",B10,C10) | G10: =G9+月別目標!B10 | H10: =前提!$B$6-F10 | I10: =IF(3=0,0,H10/3)
A11: 2027-02 | B11: =月別目標!G11 | D11: =IF(C11="","",C11-B11) | E11: =E10+B11 | F11: =F10+IF(C11="",B11,C11) | G11: =G10+月別目標!B11 | H11: =前提!$B$6-F11 | I11: =IF(2=0,0,H11/2)
A12: 2027-03 | B12: =月別目標!G12 | D12: =IF(C12="","",C12-B12) | E12: =E11+B12 | F12: =F11+IF(C12="",B12,C12) | G12: =G11+月別目標!B12 | H12: =前提!$B$6-F12 | I12: =IF(1=0,0,H12/1)
A13: 2027-04 | B13: =月別目標!G13 | D13: =IF(C13="","",C13-B13) | E13: =E12+B13 | F13: =F12+IF(C13="",B13,C13) | G13: =G12+月別目標!B13 | H13: =前提!$B$6-F13 | I13: =0
