Workbook

Sheet 前提
A1: 広告予算計画 2026-05〜2027-04（税抜）― 前提・入力値 2026-09-14 改訂（上限を税込1,200万に統一）
A2: 青字＝入力値、黄色＝仮置き（他ストアの実績や方針で差し替え）。他シートは全てこのシートを参照。方針: アウトレット品は広告しない／広告口座は FULLMARKS広告運用(Meta)・FULLMARKS Inc.(Google) のみ。
A4: 年間広告費上限（4ストア合計・税込） | B4: 12000000 | C4: 会社の上限は税込1,200万（2026-09-14 ユーザー確認）
A5: 3ストア各社の予算シェア（10月〜、各） | B5: 0 | C5: 他ECは実施が決まるまで0%（2026-09-28 ユーザー指示）。通常運用は全額 FULLMARKS。開店が決まったら各15%などに変更
A6: 9月 通常運用（FULLMARKS） | B6: 637248 | C6: 9月 確定実績 ¥637,248（日割 ¥21,241）。予算65万の98%。イベント枠は含まない
A7: 消費税率（÷で税抜換算） | B7: 1.1
A8: 年間広告費上限（税抜換算）← 以下の計画はすべてこの税抜額で管理 | B8: =B4/B7 | C8: 媒体（Google/Meta）の管理画面・API消化額は税抜。消費税は請求書で上乗せされる
A9: 実績（5〜8月）
A10: 月 | B10: FULLMARKS | C10: その他(MDX等) | D10: 合計 | E10: 備考
A11: 2026-05 | B11: 280564 | C11: 0 | D11: =B11+C11 | E11: FULLMARKS API実績
A12: 2026-06 | B12: 298599 | C12: 651401 | D12: =B12+C12 | E12: 月合計95万（ユーザー提供）。差額はMDX管理口座等
A13: 2026-07 | B13: 328194 | C13: 621806 | D13: =B13+C13 | E13: 月合計95万（ユーザー提供）
A14: 2026-08 | B14: 468641 | C14: 147557 | D14: =B14+C14 | E14: FULLMARKS API実績 + 広告代理店請求 税込162,313円→税抜147,557円（2026-09-14 ユーザー提供）
A15: 5〜8月 計 | B15: =SUM(B11:B14) | C15: =SUM(C11:C14) | D15: =SUM(D11:D14)
A18: イベント予備費（通常運用と別枠。終わった企画は使った分だけを計上）
A19: 月 | B19: 内容 | C19: 金額
A20: 2026-09 | B20: SW企画 実績（予備費 税込10万のうち使用分） | C20: 48422
A21: 2026-11 | B21: ブラックフライデー（他社と同日程・約4日間。11月の通常運用から10万を移す） | C21: 100000
A22: 2026-12 | B22: 年末年始企画 | C22: 100000
A23: 2027-02 | B23: 冬セール | C23: 250000
A24: 2027-03 | B24: イベント告知予備 | C24: 50000
A25: 計 | C25: =SUM(C20:C24)
A27: 10〜4月 通常運用の月別配分比率（繁忙期に厚く。4月は残額調整）
A28: 月 | B28: 比率
A29: 2026-10 | B29: 0.11575
A30: 2026-11 | B30: 0.16449
A31: 2026-12 | B31: 0.18727
A32: 2027-01 | B32: 0.14203
A33: 2027-02 | B33: 0.16231
A34: 2027-03 | B34: 0.11666
A35: 2027-04 | B35: 0.11
A36: 計（100%） | B36: =SUM(B29:B35)
A37: 10〜4月 通常運用の総額（上限−実績−9月−イベント） | B37: =前提!$B$8-前提!$D$15-前提!$B$6-前提!$C$25
A38: 10月 通常運用の確定実績（月末に入力。空欄なら計画どおり）
A39: 10月の使い残し（11月・12月に比率で上乗せ。2026-10-14 ユーザー指示） | B39: =IF(ISBLANK(前提!$B$38),0,前提!$B$37*前提!$B$29-前提!$B$38)
A41: FULLMARKS 内のブランド配分比率
A42: ブランド/枠 | B42: 9月 比率 | C42: 10月〜 比率 | D42: 備考
A43: HOUDINI | B43: 0.27 | C43: 0.26 | D43: 広告売上の半分以上（9月 ROAS 11.8）。FULLMARKS で継続
A44: 商品連動(ショッピング/カタログ) | B44: 0.3 | C44: 0.23 | D44: 通常価格品のみ（アウトレットは広告しない）。9月 ROAS: カタログ 4.6 / ショッピング 2.5。ショッピングを絞る
A45: 店舗指名(フルマークス) | B45: 0.17 | C45: 0.18 | D45: 9月 ROAS 16.2 の安定枠
...

Sheet 月別予算
A1: 月別 広告予算（税抜）― 4ストア合計で年間 税込1,200万（税抜 約1,091万）
A2: 通常運用＝上限−実績−9月−イベント予備費 を10〜4月の比率で配分。他ECは実施が決まるまで0（前提!B5）で、全額 FULLMARKS。
A4: 月 | B4: 区分 | C4: FULLMARKS | D4: HOUDINI STORE | E4: NORRONA STORE | F4: PU STORE | G4: その他(実績) | H4: 通常運用 計 | I4: イベント予備費 | J4: 月合計 | K4: 累計 | L4: 上限までの残り | M4: 備考
A5: 2026-05 | B5: 実績 | C5: =前提!B11 | D5: 0 | E5: 0 | F5: 0 | G5: =前提!C11 | H5: =C5+D5+E5+F5+G5 | I5: 0 | J5: =H5+I5 | K5: =J5 | L5: =前提!$B$8-K5 | M5: FULLMARKS API実績
A6: 2026-06 | B6: 実績 | C6: =前提!B12 | D6: 0 | E6: 0 | F6: 0 | G6: =前提!C12 | H6: =C6+D6+E6+F6+G6 | I6: 0 | J6: =H6+I6 | K6: =K5+J6 | L6: =前提!$B$8-K6 | M6: 月合計95万（ユーザー提供）。差額はMDX管理口座等
A7: 2026-07 | B7: 実績 | C7: =前提!B13 | D7: 0 | E7: 0 | F7: 0 | G7: =前提!C13 | H7: =C7+D7+E7+F7+G7 | I7: 0 | J7: =H7+I7 | K7: =K6+J7 | L7: =前提!$B$8-K7 | M7: 月合計95万（ユーザー提供）
A8: 2026-08 | B8: 実績 | C8: =前提!B14 | D8: 0 | E8: 0 | F8: 0 | G8: =前提!C14 | H8: =C8+D8+E8+F8+G8 | I8: 0 | J8: =H8+I8 | K8: =K7+J8 | L8: =前提!$B$8-K8 | M8: FULLMARKS API実績 + 広告代理店請求 税込162,313円→税抜147,557円（2026-09-14 ユーザー提供）
A9: 2026-09 | B9: 実績 | C9: =前提!$B$6 | D9: 0 | E9: 0 | F9: 0 | G9: 0 | H9: =C9+D9+E9+F9+G9 | I9: =前提!C20 | J9: =H9+I9 | K9: =K8+J9 | L9: =前提!$B$8-K9 | M9: FULLMARKSのみ。9月 確定実績 ¥637,248。SW企画は使用分 ¥48,422 を別枠で計上（予備費の残りは10〜4月へ）
A10: 2026-10 | B10: 計画 | C10: =H10-D10-E10-F10 | D10: =ROUND(H10*前提!$B$5,0) | E10: =ROUND(H10*前提!$B$5,0) | F10: =ROUND(H10*前提!$B$5,0) | G10: 0 | H10: =IF(ISBLANK(前提!$B$38),前提!$B$37*前提!$B$29,前提!$B$38) | I10: 0 | J10: =H10+I10 | K10: =K9+J10 | L10: =前提!$B$8-K10 | M10: 冬物の立ち上がり前。約80万に抑え、使い残しも11〜12月の通常品の冬物へ回す（10/14 ユーザー指示）
A11: 2026-11 | B11: 計画 | C11: =H11-D11-E11-F11 | D11: =ROUND(H11*前提!$B$5,0) | E11: =ROUND(H11*前提!$B$5,0) | F11: =ROUND(H11*前提!$B$5,0) | G11: 0 | H11: =前提!$B$37*前提!$B$30+前提!$B$39*前提!$B$30/(前提!$B$30+前提!$B$31) | I11: =前提!C21 | J11: =H11+I11 | K11: =K10+J11 | L11: =前提!$B$8-K11 | M11: 10月の使い残しを上乗せ（ブラックフライデー期間に厚く）
A12: 2026-12 | B12: 計画 | C12: =H12-D12-E12-F12 | D12: =ROUND(H12*前提!$B$5,0) | E12: =ROUND(H12*前提!$B$5,0) | F12: =ROUND(H12*前提!$B$5,0) | G12: 0 | H12: =前提!$B$37*前提!$B$31+前提!$B$39*前提!$B$31/(前提!$B$30+前提!$B$31) | I12: =前提!C22 | J12: =H12+I12 | K12: =K11+J12 | L12: =前提!$B$8-K12 | M12: 10月の使い残しを上乗せ。年末年始企画 予備10万
A13: 2027-01 | B13: 計画 | C13: =H13-D13-E13-F13 | D13: =ROUND(H13*前提!$B$5,0) | E13: =ROUND(H13*前提!$B$5,0) | F13: =ROUND(H13*前提!$B$5,0) | G13: 0 | H13: =前提!$B$37*前提!$B$32 | I13: 0 | J13: =H13+I13 | K13: =K12+J13 | L13: =前提!$B$8-K13
A14: 2027-02 | B14: 計画 | C14: =H14-D14-E14-F14 | D14: =ROUND(H14*前提!$B$5,0) | E14: =ROUND(H14*前提!$B$5,0) | F14: =ROUND(H14*前提!$B$5,0) | G14: 0 | H14: =前提!$B$37*前提!$B$33 | I14: =前提!C23 | J14: =H14+I14 | K14: =K13+J14 | L14: =前提!$B$8-K14 | M14: 冬セール 予備25万
A15: 2027-03 | B15: 計画 | C15: =H15-D15-E15-F15 | D15: =ROUND(H15*前提!$B$5,0) | E15: =ROUND(H15*前提!$B$5,0) | F15: =ROUND(H15*前提!$B$5,0) | G15: 0 | H15: =前提!$B$37*前提!$B$34 | I15: =前提!C24 | J15: =H15+I15 | K15: =K14+J15 | L15: =前提!$B$8-K15 | M15: イベント告知予備5万
A16: 2027-04 | B16: 計画 | C16: =H16-D16-E16-F16 | D16: =ROUND(H16*前提!$B$5,0) | E16: =ROUND(H16*前提!$B$5,0) | F16: =ROUND(H16*前提!$B$5,0) | G16: 0 | H16: =前提!$B$37-SUM(H10:H15) | I16: 0 | J16: =H16+I16 | K16: =K15+J16 | L16: =前提!$B$8-K16 | M16: 調整月（残額を全額割当）
A17: 年間合計 | C17: =SUM(C5:C16) | D17: =SUM(D5:D16) | E17: =SUM(E5:E16) | F17: =SUM(F5:F16) | G17: =SUM(G5:G16) | H17: =SUM(H5:H16) | I17: =SUM(I5:I16) | J17: =SUM(J5:J16) | L17: =前提!$B$8-J17 | M17: 上限までの残りが0であること

Sheet FULLMARKS内訳
A1: FULLMARKS STORE ブランド別予算（月別予算のFULLMARKS列 × 前提の比率）
A2: 最終行は差引で列合計をFULLMARKS月額に一致させる。アウトレット品はどの枠でも広告しない。
A4: ブランド/枠 | B4: 2026-09 | C4: 2026-10 | D4: 2026-11 | E4: 2026-12 | F4: 2027-01 | G4: 2027-02 | H4: 2027-03 | I4: 2027-04 | J4: 年間(9〜4月) | K4: 備考
A5: HOUDINI | B5: =ROUND(月別予算!$C$9*前提!$B$43,0) | C5: =ROUND(月別予算!$C$10*前提!$C$43,0) | D5: =ROUND(月別予算!$C$11*前提!$C$43,0) | E5: =ROUND(月別予算!$C$12*前提!$C$43,0) | F5: =ROUND(月別予算!$C$13*前提!$C$43,0) | G5: =ROUND(月別予算!$C$14*前提!$C$43,0) | H5: =ROUND(月別予算!$C$15*前提!$C$43,0) | I5: =ROUND(月別予算!$C$16*前提!$C$43,0) | J5: =SUM(B5:I5) | K5: 広告売上の半分以上（9月 ROAS 11.8）。FULLMARKS で継続
A6: 商品連動(ショッピング/カタログ) | B6: =ROUND(月別予算!$C$9*前提!$B$44,0) | C6: =ROUND(月別予算!$C$10*前提!$C$44,0) | D6: =ROUND(月別予算!$C$11*前提!$C$44,0) | E6: =ROUND(月別予算!$C$12*前提!$C$44,0) | F6: =ROUND(月別予算!$C$13*前提!$C$44,0) | G6: =ROUND(月別予算!$C$14*前提!$C$44,0) | H6: =ROUND(月別予算!$C$15*前提!$C$44,0) | I6: =ROUND(月別予算!$C$16*前提!$C$44,0) | J6: =SUM(B6:I6) | K6: 通常価格品のみ（アウトレットは広告しない）。9月 ROAS: カタログ 4.6 / ショッピング 2.5。ショッピングを絞る
A7: 店舗指名(フルマークス) | B7: =ROUND(月別予算!$C$9*前提!$B$45,0) | C7: =ROUND(月別予算!$C$10*前提!$C$45,0) | D7: =ROUND(月別予算!$C$11*前提!$C$45,0) | E7: =ROUND(月別予算!$C$12*前提!$C$45,0) | F7: =ROUND(月別予算!$C$13*前提!$C$45,0) | G7: =ROUND(月別予算!$C$14*前提!$C$45,0) | H7: =ROUND(月別予算!$C$15*前提!$C$45,0) | I7: =ROUND(月別予算!$C$16*前提!$C$45,0) | J7: =SUM(B7:I7) | K7: 9月 ROAS 16.2 の安定枠
A8: POC | B8: =ROUND(月別予算!$C$9*前提!$B$46,0) | C8: =ROUND(月別予算!$C$10*前提!$C$46,0) | D8: =ROUND(月別予算!$C$11*前提!$C$46,0) | E8: =ROUND(月別予算!$C$12*前提!$C$46,0) | F8: =ROUND(月別予算!$C$13*前提!$C$46,0) | G8: =ROUND(月別予算!$C$14*前提!$C$46,0) | H8: =ROUND(月別予算!$C$15*前提!$C$46,0) | I8: =ROUND(月別予算!$C$16*前提!$C$46,0) | J8: =SUM(B8:I8) | K8: 9月 ROAS 3.8。10月以降やや厚く
A9: NORRØNA | B9: =ROUND(月別予算!$C$9*前提!$B$47,0) | C9: =ROUND(月別予算!$C$10*前提!$C$47,0) | D9: =ROUND(月別予算!$C$11*前提!$C$47,0) | E9: =ROUND(月別予算!$C$12*前提!$C$47,0) | F9: =ROUND(月別予算!$C$13*前提!$C$47,0) | G9: =ROUND(月別予算!$C$14*前提!$C$47,0) | H9: =ROUND(月別予算!$C$15*前提!$C$47,0) | I9: =ROUND(月別予算!$C$16*前提!$C$47,0) | J9: =SUM(B9:I9) | K9: 9月 ROAS 4.1（8月 1.0 から改善）。FULLMARKS で継続
A10: ACLIMA | B10: =ROUND(月別予算!$C$9*前提!$B$48,0) | C10: =ROUND(月別予算!$C$10*前提!$C$48,0) | D10: =ROUND(月別予算!$C$11*前提!$C$48,0) | E10: =ROUND(月別予算!$C$12*前提!$C$48,0) | F10: =ROUND(月別予算!$C$13*前提!$C$48,0) | G10: =ROUND(月別予算!$C$14*前提!$C$48,0) | H10: =ROUND(月別予算!$C$15*前提!$C$48,0) | I10: =ROUND(月別予算!$C$16*前提!$C$48,0) | J10: =SUM(B10:I10) | K10: 8〜9月の売上の72%がセール品、広告 ROAS 2.6。縮小
A11: HESTRA【新規】 | B11: =ROUND(月別予算!$C$9*前提!$B$49,0) | C11: =ROUND(月別予算!$C$10*前提!$C$49,0) | D11: =ROUND(月別予算!$C$11*前提!$C$49,0) | E11: =ROUND(月別予算!$C$12*前提!$C$49,0) | F11: =ROUND(月別予算!$C$13*前提!$C$49,0) | G11: =ROUND(月別予算!$C$14*前提!$C$49,0) | H11: =ROUND(月別予算!$C$15*前提!$C$49,0) | I11: =ROUND(月別予算!$C$16*前提!$C$49,0) | J11: =SUM(B11:I11) | K11: 10〜1月が本番。売上の79%が通常品（粗利50%）。フィード未掲載の解消が前提
A12: KANG【新規】 | B12: =ROUND(月別予算!$C$9*前提!$B$50,0) | C12: =ROUND(月別予算!$C$10*前提!$C$50,0) | D12: =ROUND(月別予算!$C$11*前提!$C$50,0) | E12: =ROUND(月別予算!$C$12*前提!$C$50,0) | F12: =ROUND(月別予算!$C$13*前提!$C$50,0) | G12: =ROUND(月別予算!$C$14*前提!$C$50,0) | H12: =ROUND(月別予算!$C$15*前提!$C$50,0) | I12: =ROUND(月別予算!$C$16*前提!$C$50,0) | J12: =SUM(B12:I12) | K12: テスト枠
A13: PLUS ONE WORKS【新規】 | B13: =月別予算!$C$9-SUM(B5:B12) | C13: =月別予算!$C$10-SUM(C5:C12) | D13: =月別予算!$C$11-SUM(D5:D12) | E13: =月別予算!$C$12-SUM(E5:E12) | F13: =月別予算!$C$13-SUM(F5:F12) | G13: =月別予算!$C$14-SUM(G5:G12) | H13: =月別予算!$C$15-SUM(H5:H12) | I13: =月別予算!$C$16-SUM(I5:I12) | J13: =SUM(B13:I13) | K13: テスト枠
A14: 合計 | B14: =SUM(B5:B13) | C14: =SUM(C5:C13) | D14: =SUM(D5:D13) | E14: =SUM(E5:E13) | F14: =SUM(F5:F13) | G14: =SUM(G5:G13) | H14: =SUM(H5:H13) | I14: =SUM(I5:I13) | J14: =SUM(J5:J13)
A15: 月別予算との差（0） | B15: =B14-月別予算!$C$9 | C15: =C14-月別予算!$C$10 | D15: =D14-月別予算!$C$11 | E15: =E14-月別予算!$C$12 | F15: =F14-月別予算!$C$13 | G15: =G14-月別予算!$C$14 | H15: =H14-月別予算!$C$15 | I15: =I14-月別予算!$C$16

Sheet 実施_日予算
A1: 実施用 キャンペーン別 日予算（月予算÷日数、100円単位）
A2: 緑＝新設キャンペーン。他ECは実施が決まるまで載せない（前提!B5 を0より大きくすると 指名45% / ショッピング30% / カタログ・RTG25% で行が出る）。ショッピング・カタログはすべて通常価格品のみ（アウトレット除外）。イベント予備費は欄外。
A3: ストア | B3: ブランド/枠 | C3: 媒体 | D3: キャンペーン | E3: 2026-09 日予算 | F3: 2026-10 日予算 | G3: 2026-11 日予算 | H3: 2026-12 日予算 | I3: 2027-01 日予算 | J3: 2027-02 日予算 | K3: 2027-03 日予算 | L3: 2027-04 日予算 | M3: 2026-09 月予算 | N3: 2026-10 月予算 | O3: 2026-11 月予算 | P3: 2026-12 月予算 | Q3: 2027-01 月予算 | R3: 2027-02 月予算 | S3: 2027-03 月予算 | T3: 2027-04 月予算
A4: FULLMARKS | B4: HOUDINI | C4: Google | D4: UC_SK_1_指名_フーディ二 | E4: =ROUND(M4/30,-2) | F4: =ROUND(N4/31,-2) | G4: =ROUND(O4/30,-2) | H4: =ROUND(P4/31,-2) | I4: =ROUND(Q4/31,-2) | J4: =ROUND(R4/28,-2) | K4: =ROUND(S4/31,-2) | L4: =ROUND(T4/30,-2) | M4: =ROUND(FULLMARKS内訳!B5*0.65,0) | N4: =ROUND(FULLMARKS内訳!C5*0.65,0) | O4: =ROUND(FULLMARKS内訳!D5*0.65,0) | P4: =ROUND(FULLMARKS内訳!E5*0.65,0) | Q4: =ROUND(FULLMARKS内訳!F5*0.65,0) | R4: =ROUND(FULLMARKS内訳!G5*0.65,0) | S4: =ROUND(FULLMARKS内訳!H5*0.65,0) | T4: =ROUND(FULLMARKS内訳!I5*0.65,0)
A5: FULLMARKS | B5: HOUDINI | C5: Meta | D5: UC_DN_3_RTG_フーディニ_2608 | E5: =ROUND(M5/30,-2) | F5: =ROUND(N5/31,-2) | G5: =ROUND(O5/30,-2) | H5: =ROUND(P5/31,-2) | I5: =ROUND(Q5/31,-2) | J5: =ROUND(R5/28,-2) | K5: =ROUND(S5/31,-2) | L5: =ROUND(T5/30,-2) | M5: =ROUND(FULLMARKS内訳!B5*0.35,0) | N5: =ROUND(FULLMARKS内訳!C5*0.35,0) | O5: =ROUND(FULLMARKS内訳!D5*0.35,0) | P5: =ROUND(FULLMARKS内訳!E5*0.35,0) | Q5: =ROUND(FULLMARKS内訳!F5*0.35,0) | R5: =ROUND(FULLMARKS内訳!G5*0.35,0) | S5: =ROUND(FULLMARKS内訳!H5*0.35,0) | T5: =ROUND(FULLMARKS内訳!I5*0.35,0)
A6: FULLMARKS | B6: 商品連動(ショッピング/カタログ) | C6: Google | D6: UC_PL_5_PLA_v2（通常価格のみ） | E6: =ROUND(M6/30,-2) | F6: =ROUND(N6/31,-2) | G6: =ROUND(O6/30,-2) | H6: =ROUND(P6/31,-2) | I6: =ROUND(Q6/31,-2) | J6: =ROUND(R6/28,-2) | K6: =ROUND(S6/31,-2) | L6: =ROUND(T6/30,-2) | M6: =ROUND(FULLMARKS内訳!B6*0.45,0) | N6: =ROUND(FULLMARKS内訳!C6*0.45,0) | O6: =ROUND(FULLMARKS内訳!D6*0.45,0) | P6: =ROUND(FULLMARKS内訳!E6*0.45,0) | Q6: =ROUND(FULLMARKS内訳!F6*0.45,0) | R6: =ROUND(FULLMARKS内訳!G6*0.45,0) | S6: =ROUND(FULLMARKS内訳!H6*0.45,0) | T6: =ROUND(FULLMARKS内訳!I6*0.45,0)
A7: FULLMARKS | B7: 商品連動(ショッピング/カタログ) | C7: Meta | D7: UC_DN_3_CVS_フルマークス（ブランド別9本） | E7: =ROUND(M7/30,-2) | F7: =ROUND(N7/31,-2) | G7: =ROUND(O7/30,-2) | H7: =ROUND(P7/31,-2) | I7: =ROUND(Q7/31,-2) | J7: =ROUND(R7/28,-2) | K7: =ROUND(S7/31,-2) | L7: =ROUND(T7/30,-2) | M7: =ROUND(FULLMARKS内訳!B6*0.55,0) | N7: =ROUND(FULLMARKS内訳!C6*0.55,0) | O7: =ROUND(FULLMARKS内訳!D6*0.55,0) | P7: =ROUND(FULLMARKS内訳!E6*0.55,0) | Q7: =ROUND(FULLMARKS内訳!F6*0.55,0) | R7: =ROUND(FULLMARKS内訳!G6*0.55,0) | S7: =ROUND(FULLMARKS内訳!H6*0.55,0) | T7: =ROUND(FULLMARKS内訳!I6*0.55,0)
A8: FULLMARKS | B8: 店舗指名(フルマークス) | C8: Google | D8: UC_SK_1_指名_フルマークス | E8: =ROUND(M8/30,-2) | F8: =ROUND(N8/31,-2) | G8: =ROUND(O8/30,-2) | H8: =ROUND(P8/31,-2) | I8: =ROUND(Q8/31,-2) | J8: =ROUND(R8/28,-2) | K8: =ROUND(S8/31,-2) | L8: =ROUND(T8/30,-2) | M8: =ROUND(FULLMARKS内訳!B7*1.0,0) | N8: =ROUND(FULLMARKS内訳!C7*1.0,0) | O8: =ROUND(FULLMARKS内訳!D7*1.0,0) | P8: =ROUND(FULLMARKS内訳!E7*1.0,0) | Q8: =ROUND(FULLMARKS内訳!F7*1.0,0) | R8: =ROUND(FULLMARKS内訳!G7*1.0,0) | S8: =ROUND(FULLMARKS内訳!H7*1.0,0) | T8: =ROUND(FULLMARKS内訳!I7*1.0,0)
A9: FULLMARKS | B9: POC | C9: Google | D9: UC_SK_1_指名_ポック | E9: =ROUND(M9/30,-2) | F9: =ROUND(N9/31,-2) | G9: =ROUND(O9/30,-2) | H9: =ROUND(P9/31,-2) | I9: =ROUND(Q9/31,-2) | J9: =ROUND(R9/28,-2) | K9: =ROUND(S9/31,-2) | L9: =ROUND(T9/30,-2) | M9: =ROUND(FULLMARKS内訳!B8*0.45,0) | N9: =ROUND(FULLMARKS内訳!C8*0.45,0) | O9: =ROUND(FULLMARKS内訳!D8*0.45,0) | P9: =ROUND(FULLMARKS内訳!E8*0.45,0) | Q9: =ROUND(FULLMARKS内訳!F8*0.45,0) | R9: =ROUND(FULLMARKS内訳!G8*0.45,0) | S9: =ROUND(FULLMARKS内訳!H8*0.45,0) | T9: =ROUND(FULLMARKS内訳!I8*0.45,0)
A10: FULLMARKS | B10: POC | C10: Meta | D10: UC_DN_3_RTG_ポック_2608 | E10: =ROUND(M10/30,-2) | F10: =ROUND(N10/31,-2) | G10: =ROUND(O10/30,-2) | H10: =ROUND(P10/31,-2) | I10: =ROUND(Q10/31,-2) | J10: =ROUND(R10/28,-2) | K10: =ROUND(S10/31,-2) | L10: =ROUND(T10/30,-2) | M10: =ROUND(FULLMARKS内訳!B8*0.55,0) | N10: =ROUND(FULLMARKS内訳!C8*0.55,0) | O10: =ROUND(FULLMARKS内訳!D8*0.55,0) | P10: =ROUND(FULLMARKS内訳!E8*0.55,0) | Q10: =ROUND(FULLMARKS内訳!F8*0.55,0) | R10: =ROUND(FULLMARKS内訳!G8*0.55,0) | S10: =ROUND(FULLMARKS内訳!H8*0.55,0) | T10: =ROUND(FULLMARKS内訳!I8*0.55,0)
A11: FULLMARKS | B11: NORRØNA | C11: Google | D11: UC_SK_1_指名_ノローナ | E11: =ROUND(M11/30,-2) | F11: =ROUND(N11/31,-2) | G11: =ROUND(O11/30,-2) | H11: =ROUND(P11/31,-2) | I11: =ROUND(Q11/31,-2) | J11: =ROUND(R11/28,-2) | K11: =ROUND(S11/31,-2) | L11: =ROUND(T11/30,-2) | M11: =ROUND(FULLMARKS内訳!B9*0.6,0) | N11: =ROUND(FULLMARKS内訳!C9*0.6,0) | O11: =ROUND(FULLMARKS内訳!D9*0.6,0) | P11: =ROUND(FULLMARKS内訳!E9*0.6,0) | Q11: =ROUND(FULLMARKS内訳!F9*0.6,0) | R11: =ROUND(FULLMARKS内訳!G9*0.6,0) | S11: =ROUND(FULLMARKS内訳!H9*0.6,0) | T11: =ROUND(FULLMARKS内訳!I9*0.6,0)
A12: FULLMARKS | B12: NORRØNA | C12: Meta | D12: UC_DN_3_RTG_ノローナ_2608 | E12: =ROUND(M12/30,-2) | F12: =ROUND(N12/31,-2) | G12: =ROUND(O12/30,-2) | H12: =ROUND(P12/31,-2) | I12: =ROUND(Q12/31,-2) | J12: =ROUND(R12/28,-2) | K12: =ROUND(S12/31,-2) | L12: =ROUND(T12/30,-2) | M12: =ROUND(FULLMARKS内訳!B9*0.4,0) | N12: =ROUND(FULLMARKS内訳!C9*0.4,0) | O12: =ROUND(FULLMARKS内訳!D9*0.4,0) | P12: =ROUND(FULLMARKS内訳!E9*0.4,0) | Q12: =ROUND(FULLMARKS内訳!F9*0.4,0) | R12: =ROUND(FULLMARKS内訳!G9*0.4,0) | S12: =ROUND(FULLMARKS内訳!H9*0.4,0) | T12: =ROUND(FULLMARKS内訳!I9*0.4,0)
A13: FULLMARKS | B13: ACLIMA | C13: Meta | D13: UC_DN_4_CLK_アクリマ | E13: =ROUND(M13/30,-2) | F13: =ROUND(N13/31,-2) | G13: =ROUND(O13/30,-2) | H13: =ROUND(P13/31,-2) | I13: =ROUND(Q13/31,-2) | J13: =ROUND(R13/28,-2) | K13: =ROUND(S13/31,-2) | L13: =ROUND(T13/30,-2) | M13: =ROUND(FULLMARKS内訳!B10*0.6,0) | N13: =ROUND(FULLMARKS内訳!C10*0.6,0) | O13: =ROUND(FULLMARKS内訳!D10*0.6,0) | P13: =ROUND(FULLMARKS内訳!E10*0.6,0) | Q13: =ROUND(FULLMARKS内訳!F10*0.6,0) | R13: =ROUND(FULLMARKS内訳!G10*0.6,0) | S13: =ROUND(FULLMARKS内訳!H10*0.6,0) | T13: =ROUND(FULLMARKS内訳!I10*0.6,0)
A14: FULLMARKS | B14: ACLIMA | C14: Meta | D14: UC_DN_3_RTG_アクリマ_2608 | E14: =ROUND(M14/30,-2) | F14: =ROUND(N14/31,-2) | G14: =ROUND(O14/30,-2) | H14: =ROUND(P14/31,-2) | I14: =ROUND(Q14/31,-2) | J14: =ROUND(R14/28,-2) | K14: =ROUND(S14/31,-2) | L14: =ROUND(T14/30,-2) | M14: =ROUND(FULLMARKS内訳!B10*0.4,0) | N14: =ROUND(FULLMARKS内訳!C10*0.4,0) | O14: =ROUND(FULLMARKS内訳!D10*0.4,0) | P14: =ROUND(FULLMARKS内訳!E10*0.4,0) | Q14: =ROUND(FULLMARKS内訳!F10*0.4,0) | R14: =ROUND(FULLMARKS内訳!G10*0.4,0) | S14: =ROUND(FULLMARKS内訳!H10*0.4,0) | T14: =ROUND(FULLMARKS内訳!I10*0.4,0)
A15: FULLMARKS | B15: HESTRA【新規】 | C15: Google | D15: 【新設】UC_SK_1_指名_HESTRA | E15: =ROUND(M15/30,-2) | F15: =ROUND(N15/31,-2) | G15: =ROUND(O15/30,-2) | H15: =ROUND(P15/31,-2) | I15: =ROUND(Q15/31,-2) | J15: =ROUND(R15/28,-2) | K15: =ROUND(S15/31,-2) | L15: =ROUND(T15/30,-2) | M15: =ROUND(FULLMARKS内訳!B11*1.0,0) | N15: =ROUND(FULLMARKS内訳!C11*1.0,0) | O15: =ROUND(FULLMARKS内訳!D11*1.0,0) | P15: =ROUND(FULLMARKS内訳!E11*1.0,0) | Q15: =ROUND(FULLMARKS内訳!F11*1.0,0) | R15: =ROUND(FULLMARKS内訳!G11*1.0,0) | S15: =ROUND(FULLMARKS内訳!H11*1.0,0) | T15: =ROUND(FULLMARKS内訳!I11*1.0,0)
A16: FULLMARKS | B16: KANG【新規】 | C16: Google | D16: 【新設】UC_SK_1_指名_KANG | E16: =ROUND(M16/30,-2) | F16: =ROUND(N16/31,-2) | G16: =ROUND(O16/30,-2) | H16: =ROUND(P16/31,-2) | I16: =ROUND(Q16/31,-2) | J16: =ROUND(R16/28,-2) | K16: =ROUND(S16/31,-2) | L16: =ROUND(T16/30,-2) | M16: =ROUND(FULLMARKS内訳!B12*1.0,0) | N16: =ROUND(FULLMARKS内訳!C12*1.0,0) | O16: =ROUND(FULLMARKS内訳!D12*1.0,0) | P16: =ROUND(FULLMARKS内訳!E12*1.0,0) | Q16: =ROUND(FULLMARKS内訳!F12*1.0,0) | R16: =ROUND(FULLMARKS内訳!G12*1.0,0) | S16: =ROUND(FULLMARKS内訳!H12*1.0,0) | T16: =ROUND(FULLMARKS内訳!I12*1.0,0)
A17: FULLMARKS | B17: PLUS ONE WORKS【新規】 | C17: Google | D17: 【新設】UC_SK_1_指名_PLUS ONE WORKS | E17: =ROUND(M17/30,-2) | F17: =ROUND(N17/31,-2) | G17: =ROUND(O17/30,-2) | H17: =ROUND(P17/31,-2) | I17: =ROUND(Q17/31,-2) | J17: =ROUND(R17/28,-2) | K17: =ROUND(S17/31,-2) | L17: =ROUND(T17/30,-2) | M17: =ROUND(FULLMARKS内訳!B13*1.0,0) | N17: =ROUND(FULLMARKS内訳!C13*1.0,0) | O17: =ROUND(FULLMARKS内訳!D13*1.0,0) | P17: =ROUND(FULLMARKS内訳!E13*1.0,0) | Q17: =ROUND(FULLMARKS内訳!F13*1.0,0) | R17: =ROUND(FULLMARKS内訳!G13*1.0,0) | S17: =ROUND(FULLMARKS内訳!H13*1.0,0) | T17: =ROUND(FULLMARKS内訳!I13*1.0,0)
A18: 合計（通常運用） | E18: =SUM(E4:E17) | F18: =SUM(F4:F17) | G18: =SUM(G4:G17) | H18: =SUM(H4:H17) | I18: =SUM(I4:I17) | J18: =SUM(J4:J17) | K18: =SUM(K4:K17) | L18: =SUM(L4:L17) | ... T18: =SUM(T4:T17)
A19: イベント予備費（別枠） | M19: =月別予算!$I$9 | N19: =月別予算!$I$10 | O19: =月別予算!$I$11 | P19: =月別予算!$I$12 | Q19: =月別予算!$I$13 | R19: =月別予算!$I$14 | S19: =月別予算!$I$15 | T19: =月別予算!$I$16

Sheet 9月実績
A1: 9月 確定実績（キャンペーン別）
A3: 媒体 | B3: キャンペーン | C3: 9/1〜9/30 費用 | D3: 日割 | E3: 月換算(30日)
A4: Google | B4: UC_SK_1_指名_フーディ二 | C4: 102708 | D4: =C4/30 | E4: =D4*30
A5: Google | B5: UC_PL_5_PLA_v2 | C5: 89687 | D5: =C5/30 | E5: =D5*30
A6: Google | B6: UC_SK_1_指名_フルマークス | C6: 78045 | D6: =C6/30 | E6: =D6*30
A7: Google | B7: UC_SK_1_指名_ノローナ | C7: 47834 | D7: =C7/30 | E7: =D7*30
A8: Google | B8: UC_SK_1_指名_ポック | C8: 10780 | D8: =C8/30 | E8: =D8*30
A9: Meta | B9: UC_DN_3_CVS_フルマークス | C9: 129553 | D9: =C9/30 | E9: =D9*30
A10: Meta | B10: UC_DN_3_RTG_フーディニ_2608 | C10: 58865 | D10: =C10/30 | E10: =D10*30
A11: Meta | B11: UC_DN_4_CLK_アクリマ | C11: 33210 | D11: =C11/30 | E11: =D11*30
A12: Meta | B12: UC_DN_3_RTG_ポック_2608 | C12: 29286 | D12: =C12/30 | E12: =D12*30
A13: Meta | B13: UC_DN_3_RTG_ノローナ_2608 | C13: 29093 | D13: =C13/30 | E13: =D13*30
A14: Meta | B14: UC_DN_3_RTG_アクリマ_2608 | C14: 27751 | D14: =C14/30 | E14: =D14*30
A15: Google/Meta | B15: アウトレット枠（9/7停止） | C15: 436 | D15: =C15/30 | E15: =D15*30
A16: 合計 | C16: =SUM(C4:C15) | D16: =SUM(D4:D15) | E16: =SUM(E4:E15)
A17: 9月 通常運用計画 | E17: =前提!$B$6
A18: 差（月換算−計画） | E18: =E16-E17
A19: 注: 9/4夜〜9/6はMetaカタログ広告、9/23昼〜9/25夕はMeta全広告（利用上限到達）が停止。アウトレット枠は9/7に停止。SW企画（イベント枠）は含まない。
